<robot name="X03B">
  <mujoco>
    <compiler meshdir="./meshes" discardvisual="false" />
  </mujoco>

  <link name="pelvis">
    <inertial>
      <origin xyz="0.0019573 -1.0752E-05 0.056344" rpy="0 0 0" />
      <mass value="2" />
      <inertia ixx="0.018968" ixy="4.2654E-10" ixz="3.7162E-06" iyy="0.01665" iyz="-1.3974E-08" izz="0.015454" />
    </inertial>
    <visual>
      <origin xyz="0 0 0" rpy="0 0 0" />
      <geometry>
        <mesh filename="meshes/pelvis.STL" />
      </geometry>
      <material name="">
        <color rgba="1 1 1 1" />
      </material>
    </visual>
    <!-- <collision>
      <origin xyz="0 0 0" rpy="0 0 0" />
      <geometry>
        <mesh filename="meshes/pelvis.STL" />
      </geometry>
    </collision> -->
    <collision>
        <origin xyz="0 0 0.08"/>
        <geometry>
            <sphere radius="0.06"/>
        </geometry>
    </collision>
  </link>
  <link name="left_hip_pitch_link">
    <inertial>
      <origin xyz="-0.0008943 -0.001219 0.0084596" rpy="0 0 0" />
      <mass value="2" />
      <inertia ixx="0.0018174" ixy="2.4335E-08" ixz="2.4374E-05" iyy="0.002214" iyz="-9.5163E-06" izz="0.0016087" />
    </inertial>
    <visual>
      <origin xyz="0 0 0" rpy="0 0 0" />
      <geometry>
        <mesh filename="meshes/left_hip_pitch_link.STL" />
      </geometry>
      <material name="">
        <color rgba="1 1 1 1" />
      </material>
    </visual>
    <collision>
      <origin xyz="0 0 0" rpy="0 0 0" />
      <geometry>
        <mesh filename="meshes/left_hip_pitch_link.STL" />
      </geometry>
    </collision>
  </link>
  <joint name="left_hip_pitch_joint" type="revolute">
    <origin xyz="0 0.0975000000000006 0" rpy="0 0 0" />
    <parent link="pelvis" />
    <child link="left_hip_pitch_link" />
    <axis xyz="0 1 0" />
    <limit lower="-1.5708" upper="0.7854" effort="0" velocity="0" />
  </joint>
  <link name="left_hip_roll_link">
    <inertial>
      <origin xyz="2.5752E-05 -4.528E-07 -0.0093831" rpy="0 0 0" />
      <mass value="0.3" />
      <inertia ixx="0.00020398" ixy="-4.1454E-09" ixz="1.6055E-07" iyy="0.00016045" iyz="-2.7386E-09" izz="0.00015153" />
    </inertial>
    <visual>
      <origin xyz="0 0 0" rpy="0 0 0" />
      <geometry>
        <mesh filename="meshes/left_hip_roll_link.STL" />
      </geometry>
      <material name="">
        <color rgba="0.79216 0.81961 0.93333 1" />
      </material>
    </visual>
    <collision>
      <origin xyz="0 0 0" rpy="0 0 0" />
      <geometry>
        <mesh filename="meshes/left_hip_roll_link.STL" />
      </geometry>
    </collision>
  </link>
  <joint name="left_hip_roll_joint" type="revolute">
    <origin xyz="0 0 -0.044" rpy="0 0 0" />
    <parent link="left_hip_pitch_link" />
    <child link="left_hip_roll_link" />
    <axis xyz="1 0 0" />
    <limit lower="-0.1745" upper="1.5708" effort="0" velocity="0" />
  </joint>
  <link name="left_hip_yaw_link">
    <inertial>
      <origin xyz="0.00201125 0 -0.11612591" rpy="0 0 0" />
      <mass value="1.4" />
      <inertia ixx="0.01004499" ixy="-0.00000001" ixz="-0.00004671" iyy="0.00999163" iyz="0.00000000" izz="0.00202539" />
    </inertial>
    <visual>
      <origin xyz="0 0 0" rpy="0 0 0" />
      <geometry>
        <mesh filename="meshes/left_hip_yaw_link.STL" />
      </geometry>
      <material name="">
        <color rgba="0.79216 0.81961 0.93333 1" />
      </material>
    </visual>
    <collision>
      <origin xyz="0 0 0" rpy="0 0 0" />
      <geometry>
        <mesh filename="meshes/left_hip_yaw_link.STL" />
      </geometry>
    </collision>
  </link>
  <joint name="left_hip_yaw_joint" type="revolute">
    <origin xyz="0 0 -0.0419999999999999" rpy="0 0 0" />
    <parent link="left_hip_roll_link" />
    <child link="left_hip_yaw_link" />
    <axis xyz="0 0 -1" />
    <limit lower="-1.5708" upper="1.5708" effort="0" velocity="0" />
  </joint>
  <link name="left_knee_link">
    <inertial>
      <origin xyz="-0.00201967 0 -0.21600403" rpy="0 0 0" />
      <mass value="1" />
      <inertia ixx="0.01908488" ixy="0.00000000" ixz="-0.00006292" iyy="0.01928341" iyz="0.00000000" izz="0.00083337" />
    </inertial>
    <visual>
      <origin xyz="0 0 0" rpy="0 0 0" />
      <geometry>
        <mesh filename="meshes/left_knee_link.STL" />
      </geometry>
      <material name="">
        <color rgba="1 1 1 1" />
      </material>
    </visual>
    <collision>
      <origin xyz="0 0 0" rpy="0 0 0" />
      <geometry>
        <mesh filename="meshes/left_knee_link.STL" />
      </geometry>
    </collision>
  </link>
  <joint name="left_knee_joint" type="revolute">
    <origin xyz="0 0 -0.284" rpy="0 0 0" />
    <parent link="left_hip_yaw_link" />
    <child link="left_knee_link" />
    <axis xyz="0 1 0" />
    <limit lower="0" upper="2.3562" effort="0" velocity="0" />
  </joint>
  <link name="left_ankle_pitch_link">
    <inertial>
      <origin xyz="6.9616E-09 4.5483E-09 -0.0074946" rpy="0 0 0" />
      <mass value="0.4" />
      <inertia ixx="7.9792E-05" ixy="6.8119E-17" ixz="-5.4054E-11" iyy="9.1324E-05" iyz="-1.4466E-12" izz="3.5468E-05" />
    </inertial>
    <visual>
      <origin xyz="0 0 0" rpy="0 0 0" />
      <geometry>
        <mesh filename="meshes/left_ankle_pitch_link.STL" />
      </geometry>
      <material name="">
        <color rgba="1 1 1 1" />
      </material>
    </visual>
    <collision>
      <origin xyz="0 0 0" rpy="0 0 0" />
      <geometry>
        <mesh filename="meshes/left_ankle_pitch_link.STL" />
      </geometry>
    </collision>
  </link>
  <joint name="left_ankle_pitch_joint" type="revolute">
    <origin xyz="0 0 -0.449999999999998" rpy="0 0 0" />
    <parent link="left_knee_link" />
    <child link="left_ankle_pitch_link" />
    <axis xyz="0 1 0" />
    <limit lower="-1.0472" upper="1.0472" effort="0" velocity="0" />
  </joint>
  <link name="left_ankle_roll_link">
    <inertial>
      <origin xyz="0.025367 -1.8243E-07 -0.010325" rpy="0 0 0" />
      <mass value="0.6" />
      <inertia ixx="0.00039193" ixy="-8.6608E-09" ixz="0.00015542" iyy="0.0034177" iyz="-2.9474E-11" izz="0.0036796" />
    </inertial>
    <visual>
      <origin xyz="0 0 0" rpy="0 0 0" />
      <geometry>
        <mesh filename="meshes/left_ankle_roll_link.STL" />
      </geometry>
      <material name="">
        <color rgba="1 1 1 1" />
      </material>
    </visual>
    <!-- <collision>
      <origin xyz="0 0 0" rpy="0 0 0" />
      <geometry>
        <mesh filename="meshes/left_ankle_roll_link.STL" />
      </geometry>
    </collision> -->
    <collision><origin xyz="-0.085  0 -0.036"/><geometry><sphere radius="0.005"/></geometry></collision>
    <collision><origin xyz="-0.035  0.034 -0.036"/><geometry><sphere radius="0.005"/></geometry></collision>
    <collision><origin xyz="-0.035 -0.034 -0.036"/><geometry><sphere radius="0.005"/></geometry></collision>
    <collision><origin xyz="0.12    0.045 -0.036"/><geometry><sphere radius="0.005"/></geometry></collision>
    <collision><origin xyz="0.12   -0.045 -0.036"/><geometry><sphere radius="0.005"/></geometry></collision>
    <collision><origin xyz="0.18  0  -0.036"/><geometry><sphere radius="0.005"/></geometry></collision>
    <collision>
            <origin xyz="0.08 -0.026 -0.024" rpy="0 1.5708 0"/>
            <geometry>
                <cylinder radius="0.01" length="0.1"/>
            </geometry>
    </collision>
    <collision>
            <origin xyz="0.044 -0.018 -0.024" rpy="0 -1.5708 0"/>
            <geometry>
                <cylinder radius="0.01" length="0.2"/>
            </geometry>
    </collision>
    <collision>
            <origin xyz="0.046 -0.01 -0.024" rpy="0 -1.5708 0"/>
            <geometry>
                <cylinder radius="0.01" length="0.24"/>
            </geometry>
    </collision>
    <collision>
            <origin xyz="0.048 0 -0.024" rpy="0 -1.5708 0"/>
            <geometry>
                <cylinder radius="0.01" length="0.25"/>
            </geometry>
    </collision>
    <collision>
            <origin xyz="0.046 0.01 -0.024" rpy="0 -1.5708 0"/>
            <geometry>
                <cylinder radius="0.01" length="0.24"/>
            </geometry>
    </collision>
    <collision>
            <origin xyz="0.044 0.018 -0.024" rpy="0 -1.5708 0"/>
            <geometry>
                <cylinder radius="0.01" length="0.2"/>
            </geometry>
    </collision>
    <collision>
            <origin xyz="0.08 0.026 -0.024" rpy="0 1.5708 0"/>
            <geometry>
                <cylinder radius="0.01" length="0.1"/>
            </geometry>
    </collision>
  </link>
  <joint name="left_ankle_roll_joint" type="revolute">
    <origin xyz="0 0 -0.0579999999999991" rpy="0 0 0" />
    <parent link="left_ankle_pitch_link" />
    <child link="left_ankle_roll_link" />
    <axis xyz="1 0 0" />
    <limit lower="-0.524" upper="0.524" effort="0" velocity="0" />
  </joint>
  <link name="right_hip_pitch_link">
    <inertial>
      <origin xyz="-0.0008943 -0.001219 0.0084596" rpy="0 0 0" />
      <mass value="2" />
      <inertia ixx="0.0018174" ixy="2.4335E-08" ixz="2.4374E-05" iyy="0.002214" iyz="-9.5163E-06" izz="0.0016087" />
    </inertial>
    <visual>
      <origin xyz="0 0 0" rpy="0 0 0" />
      <geometry>
        <mesh filename="meshes/right_hip_pitch_link.STL" />
      </geometry>
      <material name="">
        <color rgba="1 1 1 1" />
      </material>
    </visual>
    <collision>
      <origin xyz="0 0 0" rpy="0 0 0" />
      <geometry>
        <mesh filename="meshes/right_hip_pitch_link.STL" />
      </geometry>
    </collision>
  </link>
  <joint name="right_hip_pitch_joint" type="revolute">
    <origin xyz="0 -0.0975000000000001 0" rpy="0 0 0" />
    <parent link="pelvis" />
    <child link="right_hip_pitch_link" />
    <axis xyz="0 1 0" />
    <limit lower="-1.5708" upper="0.7854" effort="0" velocity="0" />
  </joint>
  <link name="right_hip_roll_link">
    <inertial>
      <origin xyz="2.5751E-05 -4.4797E-07 -0.0093831" rpy="0 0 0" />
      <mass value="0.3" />
      <inertia ixx="0.00020398" ixy="-4.1587E-09" ixz="1.6054E-07" iyy="0.00016045" iyz="-2.7012E-09" izz="0.00015153" />
    </inertial>
    <visual>
      <origin xyz="0 0 0" rpy="0 0 0" />
      <geometry>
        <mesh filename="meshes/right_hip_roll_link.STL" />
      </geometry>
      <material name="">
        <color rgba="0.79216 0.81961 0.93333 1" />
      </material>
    </visual>
    <collision>
      <origin xyz="0 0 0" rpy="0 0 0" />
      <geometry>
        <mesh filename="meshes/right_hip_roll_link.STL" />
      </geometry>
    </collision>
  </link>
  <joint name="right_hip_roll_joint" type="revolute">
    <origin xyz="0 0 -0.044" rpy="0 0 0" />
    <parent link="right_hip_pitch_link" />
    <child link="right_hip_roll_link" />
    <axis xyz="1 0 0" />
    <limit lower="-1.5708" upper="0.1745" effort="0" velocity="0" />
  </joint>
  <link name="right_hip_yaw_link">
    <inertial>
      <origin xyz="0.00201125 0 -0.11612591" rpy="0 0 0" />
      <mass value="1.4" />
      <inertia ixx="0.01004499" ixy="-0.00000001" ixz="-0.00004671" iyy="0.00999163" iyz="0.00000000" izz="0.00202539" />
    </inertial>
    <visual>
      <origin xyz="0 0 0" rpy="0 0 0" />
      <geometry>
        <mesh filename="meshes/right_hip_yaw_link.STL" />
      </geometry>
      <material name="">
        <color rgba="0.79216 0.81961 0.93333 1" />
      </material>
    </visual>
    <collision>
      <origin xyz="0 0 0" rpy="0 0 0" />
      <geometry>
        <mesh filename="meshes/right_hip_yaw_link.STL" />
      </geometry>
    </collision>
  </link>
  <joint name="right_hip_yaw_joint" type="revolute">
    <origin xyz="0 0 -0.042" rpy="0 0 0" />
    <parent link="right_hip_roll_link" />
    <child link="right_hip_yaw_link" />
    <axis xyz="0 0 1" />
    <limit lower="-1.5708" upper="1.5708" effort="0" velocity="0" />
  </joint>
  <link name="right_knee_link">
    <inertial>
      <origin xyz="-0.00201967 0 -0.21600403" rpy="0 0 0" />
      <mass value="1" />
      <inertia ixx="0.01908488" ixy="0.00000000" ixz="-0.00006292" iyy="0.01928341" iyz="0.00000000" izz="0.00083337" />
    </inertial>
    <visual>
      <origin xyz="0 0 0" rpy="0 0 0" />
      <geometry>
        <mesh filename="meshes/right_knee_link.STL" />
      </geometry>
      <material name="">
        <color rgba="1 1 1 1" />
      </material>
    </visual>
    <collision>
      <origin xyz="0 0 0" rpy="0 0 0" />
      <geometry>
        <mesh filename="meshes/right_knee_link.STL" />
      </geometry>
    </collision>
  </link>
  <joint name="right_knee_joint" type="revolute">
    <origin xyz="0 0 -0.284" rpy="0 0 0" />
    <parent link="right_hip_yaw_link" />
    <child link="right_knee_link" />
    <axis xyz="0 1 0" />
    <limit lower="0" upper="2.3562" effort="0" velocity="0" />
  </joint>
  <link name="right_ankle_pitch_link">
    <inertial>
      <origin xyz="6.9616E-09 4.5483E-09 -0.0074946" rpy="0 0 0" />
      <mass value="0.4" />
      <inertia ixx="7.9792E-05" ixy="6.7961E-17" ixz="-5.4054E-11" iyy="9.1324E-05" iyz="-1.4466E-12" izz="3.5468E-05" />
    </inertial>
    <visual>
      <origin xyz="0 0 0" rpy="0 0 0" />
      <geometry>
        <mesh filename="meshes/right_ankle_pitch_link.STL" />
      </geometry>
      <material name="">
        <color rgba="1 1 1 1" />
      </material>
    </visual>
    <collision>
      <origin xyz="0 0 0" rpy="0 0 0" />
      <geometry>
        <mesh filename="meshes/right_ankle_pitch_link.STL" />
      </geometry>
    </collision>
  </link>
  <joint name="right_ankle_pitch_joint" type="revolute">
    <origin xyz="0 0 -0.449999999999999" rpy="0 0 0" />
    <parent link="right_knee_link" />
    <child link="right_ankle_pitch_link" />
    <axis xyz="0 1 0" />
    <limit lower="-1.0472" upper="1.0472" effort="0" velocity="0" />
  </joint>
  <link name="right_ankle_roll_link">
    <inertial>
      <origin xyz="0.025367 -1.8287E-07 -0.010325" rpy="0 0 0" />
      <mass value="0.6" />
      <inertia ixx="0.00039193" ixy="-8.6276E-09" ixz="0.00015542" iyy="0.0034177" iyz="-3.2223E-11" izz="0.0036796" />
    </inertial>
    <visual>
      <origin xyz="0 0 0" rpy="0 0 0" />
      <geometry>
        <mesh filename="meshes/right_ankle_roll_link.STL" />
      </geometry>
      <material name="">
        <color rgba="1 1 1 1" />
      </material>
    </visual>
    <!-- <collision>
      <origin xyz="0 0 0" rpy="0 0 0" />
      <geometry>
        <mesh filename="meshes/right_ankle_roll_link.STL" />
      </geometry>
    </collision> -->
    <collision><origin xyz="-0.085  0 -0.036"/><geometry><sphere radius="0.005"/></geometry></collision>
    <collision><origin xyz="-0.035  0.034 -0.036"/><geometry><sphere radius="0.005"/></geometry></collision>
    <collision><origin xyz="-0.035 -0.034 -0.036"/><geometry><sphere radius="0.005"/></geometry></collision>
    <collision><origin xyz="0.12    0.045 -0.036"/><geometry><sphere radius="0.005"/></geometry></collision>
    <collision><origin xyz="0.12   -0.045 -0.036"/><geometry><sphere radius="0.005"/></geometry></collision>
    <collision><origin xyz="0.18  0  -0.036"/><geometry><sphere radius="0.005"/></geometry></collision>
    <collision>
            <origin xyz="0.08 -0.026 -0.024" rpy="0 1.5708 0"/>
            <geometry>
                <cylinder radius="0.01" length="0.1"/>
            </geometry>
    </collision>
    <collision>
            <origin xyz="0.044 -0.018 -0.024" rpy="0 -1.5708 0"/>
            <geometry>
                <cylinder radius="0.01" length="0.2"/>
            </geometry>
    </collision>
    <collision>
            <origin xyz="0.046 -0.01 -0.024" rpy="0 -1.5708 0"/>
            <geometry>
                <cylinder radius="0.01" length="0.24"/>
            </geometry>
    </collision>
    <collision>
            <origin xyz="0.048 0 -0.024" rpy="0 -1.5708 0"/>
            <geometry>
                <cylinder radius="0.01" length="0.25"/>
            </geometry>
    </collision>
    <collision>
            <origin xyz="0.046 0.01 -0.024" rpy="0 -1.5708 0"/>
            <geometry>
                <cylinder radius="0.01" length="0.24"/>
            </geometry>
    </collision>
    <collision>
            <origin xyz="0.044 0.018 -0.024" rpy="0 -1.5708 0"/>
            <geometry>
                <cylinder radius="0.01" length="0.2"/>
            </geometry>
    </collision>
    <collision>
            <origin xyz="0.08 0.026 -0.024" rpy="0 1.5708 0"/>
            <geometry>
                <cylinder radius="0.01" length="0.1"/>
            </geometry>
    </collision>
  </link>
  <joint name="right_ankle_roll_joint" type="revolute">
    <origin xyz="0 0 -0.0579999999999992" rpy="0 0 0" />
    <parent link="right_ankle_pitch_link" />
    <child link="right_ankle_roll_link" />
    <axis xyz="1 0 0" />
    <limit lower="-0.524" upper="0.524" effort="0" velocity="0" />
  </joint>
  <link name="waist_roll_link">
    <inertial>
      <origin xyz="0.0020869 -9.8997E-08 0.027535" rpy="0 0 0" />
      <mass value="1.5" />
      <inertia ixx="0.00083753" ixy="-4.0056E-09" ixz="-1.5131E-06" iyy="0.0011951" iyz="5.2634E-10" izz="0.0017744" />
    </inertial>
    <visual>
      <origin xyz="0 0 0" rpy="0 0 0" />
      <geometry>
        <mesh filename="meshes/waist_roll_link.STL" />
      </geometry>
      <material name="">
        <color rgba="1 1 1 1" />
      </material>
    </visual>
    <collision>
      <origin xyz="0 0 0" rpy="0 0 0" />
      <geometry>
        <mesh filename="meshes/waist_roll_link.STL" />
      </geometry>
    </collision>
  </link>
  <joint name="waist_roll_joint" type="revolute">
    <origin xyz="0 0 0.1525" rpy="0 0 0" />
    <parent link="pelvis" />
    <child link="waist_roll_link" />
    <axis xyz="-1 0 0" />
    <limit lower="-0.3491" upper="0.3491" effort="0" velocity="0" />
  </joint>
  <link name="waist_yaw_link">
    <inertial>
      <origin xyz="4.4409E-16 0 0.0535" rpy="0 0 0" />
      <mass value="0.1" />
      <inertia ixx="1.0472E-07" ixy="1.3356E-24" ixz="2.7573E-25" iyy="1.0472E-07" iyz="2.2058E-24" izz="1.5708E-07" />
    </inertial>
    <visual>
      <origin xyz="0 0 0" rpy="0 0 0" />
      <geometry>
        <mesh filename="meshes/waist_yaw_link.STL" />
      </geometry>
      <material name="">
        <color rgba="1 1 1 1" />
      </material>
    </visual>
    <collision>
      <origin xyz="0 0 0" rpy="0 0 0" />
      <geometry>
        <mesh filename="meshes/waist_yaw_link.STL" />
      </geometry>
    </collision>
  </link>
  <joint name="waist_yaw_joint" type="revolute">
    <origin xyz="0 0 0" rpy="0 0 0" />
    <parent link="waist_roll_link" />
    <child link="waist_yaw_link" />
    <axis xyz="0 0 1" />
    <limit lower="-1.5708" upper="1.5708" effort="0" velocity="0" />
  </joint>
  <link name="torso_link">
    <inertial>
      <origin xyz="0.0035481 -2.2396E-07 0.13946" rpy="0 0 0" />
      <mass value="9.9" />
      <inertia ixx="0.017698" ixy="-4.392E-08" ixz="-3.9036E-05" iyy="0.017346" iyz="1.895E-08" izz="0.016621" />
    </inertial>
    <visual>
      <origin xyz="0 0 0" rpy="0 0 0" />
      <geometry>
        <mesh filename="meshes/torso_link.STL" />
      </geometry>
      <material name="">
        <color rgba="1 1 1 1" />
      </material>
    </visual>
    <collision>
      <origin xyz="0 0 0" rpy="0 0 0" />
      <geometry>
        <mesh filename="meshes/torso_link.STL" />
      </geometry>
    </collision>
  </link>
  <joint name="torso_joint" type="fixed">
    <origin xyz="0 0 0" rpy="0 0 0" />
    <parent link="waist_yaw_link" />
    <child link="torso_link" />
    <axis xyz="0 0 0" />
  </joint>
  <link name="head_pitch_link">
    <inertial>
      <origin xyz="-9.0916E-09 5.1765E-09 0.0034789" rpy="0 0 0" />
      <mass value="0.5" />
      <inertia ixx="7.0972E-07" ixy="2.1771E-11" ixz="7.9633E-13" iyy="6.7519E-07" iyz="-3.7469E-13" izz="4.9986E-07" />
    </inertial>
    <visual>
      <origin xyz="0 0 0" rpy="0 0 0" />
      <geometry>
        <mesh filename="meshes/head_pitch_link.STL" />
      </geometry>
      <material name="">
        <color rgba="1 1 1 1" />
      </material>
    </visual>
    <collision>
      <origin xyz="0 0 0" rpy="0 0 0" />
      <geometry>
        <mesh filename="meshes/head_pitch_link.STL" />
      </geometry>
    </collision>
  </link>
  <joint name="head_pitch_joint" type="fixed">
    <origin xyz="-0.0150000000000001 1.03068293899611E-05 0.3815" rpy="0 0 0" />
    <parent link="torso_link" />
    <child link="head_pitch_link" />
    <axis xyz="0 0 0" />
    <limit lower="0" upper="0" effort="0" velocity="0" />
  </joint>
  <link name="head_yaw_link">
    <inertial>
      <origin xyz="0.014736 0.00089129 0.11887" rpy="0 0 0" />
      <mass value="3" />
      <inertia ixx="0.0078721" ixy="7.4285E-07" ixz="0.00043122" iyy="0.0066172" iyz="-3.1899E-06" izz="0.0036833" />
    </inertial>
    <visual>
      <origin xyz="0 0 0" rpy="0 0 0" />
      <geometry>
        <mesh filename="meshes/head_yaw_link.STL" />
      </geometry>
      <material name="">
        <color rgba="1 1 1 1" />
      </material>
    </visual>
    <collision>
      <origin xyz="0 0 0" rpy="0 0 0" />
      <geometry>
        <mesh filename="meshes/head_yaw_link.STL" />
      </geometry>
    </collision>
  </link>
  <joint name="head_yaw_joint" type="fixed">
    <origin xyz="0 0 0" rpy="0 0 0" />
    <parent link="head_pitch_link" />
    <child link="head_yaw_link" />
    <axis xyz="0 0 0" />
    <limit lower="0" upper="0" effort="0" velocity="0" />
  </joint>
  <link name="left_shoulder_pitch_link">
    <inertial>
      <origin xyz="-2.1187E-08 0.055283 -3.2729E-10" rpy="0 0 0" />
      <mass value="0.8" />
      <inertia ixx="0.00059731" ixy="-2.1296E-11" ixz="1.6798E-10" iyy="0.00060184" iyz="-1.3626E-09" izz="0.00056165" />
    </inertial>
    <!-- <visual>
      <origin xyz="0 0 0" rpy="0 0 0" />
      <geometry>
        <mesh filename="meshes/left_shoulder_pitch_link.STL" />
      </geometry>
      <material name="">
        <color rgba="1 1 1 1" />
      </material>
    </visual>
    <collision>
      <origin xyz="0 0 0" rpy="0 0 0" />
      <geometry>
        <mesh filename="meshes/left_shoulder_pitch_link.STL" />
      </geometry>
    </collision> -->
  </link>
  <joint name="left_shoulder_pitch_joint" type="revolute">
    <origin xyz="-0.0150000000016766 0.0835112359330128 0.286500000005521" rpy="0 0 0" />
    <parent link="torso_link" />
    <child link="left_shoulder_pitch_link" />
    <axis xyz="0 1 0" />
    <limit lower="-3.1416" upper="1.5708" effort="0" velocity="0" />
  </joint>
  <link name="left_shoulder_roll_link">
    <inertial>
      <origin xyz="-0.0011333 0.00054145 -0.0024787" rpy="0 0 0" />
      <mass value="0.2" />
      <inertia ixx="0.000111" ixy="-3.9009E-09" ixz="-3.9963E-08" iyy="7.1762E-05" iyz="1.8436E-06" izz="7.126E-05" />
    </inertial>
    <!-- <visual>
      <origin xyz="0 0 0" rpy="0 0 0" />
      <geometry>
        <mesh filename="meshes/left_shoulder_roll_link.STL" />
      </geometry>
      <material name="">
        <color rgba="1 1 1 1" />
      </material>
    </visual>
    <collision>
      <origin xyz="0 0 0" rpy="0 0 0" />
      <geometry>
        <mesh filename="meshes/left_shoulder_roll_link.STL" />
      </geometry>
    </collision> -->
    <collision>
      <origin xyz="0 0 0"/>
      <geometry>
          <sphere radius="0.025"/>
      </geometry>
    </collision>
  </link>
  <joint name="left_shoulder_roll_joint" type="revolute">
    <origin xyz="0 0.07399527579835 0" rpy="0 0 0" />
    <parent link="left_shoulder_pitch_link" />
    <child link="left_shoulder_roll_link" />
    <axis xyz="1 0 0" />
    <limit lower="-0.1222" upper="2.0944" effort="0" velocity="0" />
  </joint>
  <link name="left_shoulder_yaw_link">
    <inertial>
      <origin xyz="-0.0010112 3.4167E-05 -0.096956" rpy="0 0 0" />
      <mass value="1.7" />
      <inertia ixx="0.0026061" ixy="-1.2818E-08" ixz="-5.8542E-06" iyy="0.002525" iyz="-7.7049E-06" izz="0.00054206" />
    </inertial>
    <!-- <visual>
      <origin xyz="0 0 0" rpy="0 0 0" />
      <geometry>
        <mesh filename="meshes/left_shoulder_yaw_link.STL" />
      </geometry>
      <material name="">
        <color rgba="1 1 1 1" />
      </material>
    </visual>
    <collision>
      <origin xyz="0 0 0" rpy="0 0 0" />
      <geometry>
        <mesh filename="meshes/left_shoulder_yaw_link.STL" />
      </geometry>
    </collision> -->
    <collision>
      <origin xyz="0 0 -0.07" rpy="3.1416 0 0"/>
      <geometry>
          <cylinder radius="0.030" length="0.13"/>
      </geometry>
    </collision>
  </link>
  <joint name="left_shoulder_yaw_joint" type="revolute">
    <origin xyz="0 0.00256631167321908 -0.0369111569683327" rpy="0.0693126999225227 0 0" />
    <parent link="left_shoulder_roll_link" />
    <child link="left_shoulder_yaw_link" />
    <axis xyz="0 0 1" />
    <limit lower="-0.7854" upper="0.7854" effort="0" velocity="0" />
  </joint>
  <link name="left_elbow_link">
    <inertial>
      <origin xyz="0.00058454 3.3764E-10 0.0012698" rpy="0 0 0" />
      <mass value="0.6" />
      <inertia ixx="5.5486E-05" ixy="1.697E-14" ixz="-4.5201E-08" iyy="8.3729E-05" iyz="-5.3251E-11" izz="5.3989E-05" />
    </inertial>
    <!-- <visual>
      <origin xyz="0 0 0" rpy="0 0 0" />
      <geometry>
        <mesh filename="meshes/left_elbow_link.STL" />
      </geometry>
      <material name="">
        <color rgba="1 1 1 1" />
      </material>
    </visual>
    <collision>
      <origin xyz="0 0 0" rpy="0 0 0" />
      <geometry>
        <mesh filename="meshes/left_elbow_link.STL" />
      </geometry>
    </collision> -->
    <collision>
      <origin xyz="0 0 0"/>
      <geometry>
          <sphere radius="0.03"/>
      </geometry>
    </collision>
  </link>
  <joint name="left_elbow_joint" type="revolute">
    <origin xyz="0 0 -0.193" rpy="0 0 0" />
    <parent link="left_shoulder_yaw_link" />
    <child link="left_elbow_link" />
    <axis xyz="0 1 0" />
    <limit lower="-0.5236" upper="1.5708" effort="0" velocity="0" />
  </joint>
  <link name="left_wrist_roll_link">
    <inertial>
      <origin xyz="0.09449 0.0006287 0.0003023" rpy="0 0 0" />
      <mass value="1.1" />
      <inertia ixx="0.00025229" ixy="-1.5559E-05" ixz="1.8368E-05" iyy="0.0018327" iyz="1.7024E-07" izz="0.0018096" />
    </inertial>
    <!-- <visual>
      <origin xyz="0 0 0" rpy="0 0 0" />
      <geometry>
        <mesh filename="meshes/left_wrist_roll_link.STL" />
      </geometry>
      <material name="">
        <color rgba="1 1 1 1" />
      </material>
    </visual>
    <collision>
      <origin xyz="0 0 0" rpy="0 0 0" />
      <geometry>
        <mesh filename="meshes/left_wrist_roll_link.STL" />
      </geometry>
    </collision> -->
    <collision>
      <origin xyz="0.1 0 0" rpy="0 1.57 0"/>
      <geometry>
          <cylinder radius="0.030" length="0.18"/>
      </geometry>
    </collision>
  </link>
  <joint name="left_wrist_roll_joint" type="revolute">
    <origin xyz="0.0319999999680638 0 0" rpy="0 0 0" />
    <parent link="left_elbow_link" />
    <child link="left_wrist_roll_link" />
    <axis xyz="1 0 0" />
    <limit lower="-0.7854" upper="0.7854" effort="0" velocity="0" />
  </joint>
  <link name="left_wrist_yaw_link">
    <inertial>
      <origin xyz="0.01075 4.4409E-16 1.1102E-16" rpy="0 0 0" />
      <mass value="0.1" />
      <inertia ixx="2.0918E-06" ixy="-8.3991E-20" ixz="5.0423E-21" iyy="3.7169E-06" iyz="2.1705E-21" izz="3.7169E-06" />
    </inertial>
    <visual>
      <origin xyz="0 0 0" rpy="0 0 0" />
      <geometry>
        <mesh filename="meshes/left_wrist_yaw_link.STL" />
      </geometry>
      <material name="">
        <color rgba="1 1 1 1" />
      </material>
    </visual>
    <collision>
      <origin xyz="0 0 0" rpy="0 0 0" />
      <geometry>
        <mesh filename="meshes/left_wrist_yaw_link.STL" />
      </geometry>
    </collision>
  </link>
  <joint name="left_wrist_yaw_joint" type="fixed">
    <origin xyz="0.203 0 0" rpy="0 0 0" />
    <parent link="left_wrist_roll_link" />
    <child link="left_wrist_yaw_link" />
    <axis xyz="0 0 1" />
    <limit lower="-1.0472" upper="1.0472" effort="0" velocity="0" />
  </joint>
  <link name="left_wrist_pitch_link">
    <inertial>
      <origin xyz="0.063609 0.00066333 0.0046234" rpy="0 0 0" />
      <mass value="0.6" />
      <inertia ixx="0.00020175" ixy="1.8409E-05" ixz="-6.2532E-06" iyy="0.00055219" iyz="3.213E-05" izz="0.00044197" />
    </inertial>
    <visual>
      <origin xyz="0 0 0" rpy="0 0 0" />
      <geometry>
        <mesh filename="meshes/left_wrist_pitch_link.STL" />
      </geometry>
      <material name="">
        <color rgba="1 1 1 1" />
      </material>
    </visual>
    <collision>
      <origin xyz="0 0 0" rpy="0 0 0" />
      <geometry>
        <mesh filename="meshes/left_wrist_pitch_link.STL" />
      </geometry>
    </collision>
  </link>
  <joint name="left_wrist_pitch_joint" type="fixed">
    <origin xyz="0.0215000000000023 0 0" rpy="0 0 0" />
    <parent link="left_wrist_yaw_link" />
    <child link="left_wrist_pitch_link" />
    <axis xyz="0 1 0" />
    <limit lower="-0.5236" upper="0.5236" effort="0" velocity="0" />
  </joint>
  <link name="right_shoulder_pitch_link">
    <inertial>
      <origin xyz="2.1275E-08 -0.055283 -4.7153E-10" rpy="0 0 0" />
      <mass value="0.8" />
      <inertia ixx="0.00059731" ixy="-2.2279E-11" ixz="-1.6762E-10" iyy="0.00060184" iyz="1.3612E-09" izz="0.00056165" />
    </inertial>
    <!-- <visual>
      <origin xyz="0 0 0" rpy="0 0 0" />
      <geometry>
        <mesh filename="meshes/right_shoulder_pitch_link.STL" />
      </geometry>
      <material name="">
        <color rgba="1 1 1 1" />
      </material>
    </visual>
    <collision>
      <origin xyz="0 0 0" rpy="0 0 0" />
      <geometry>
        <mesh filename="meshes/right_shoulder_pitch_link.STL" />
      </geometry>
    </collision> -->
  </link>
  <joint name="right_shoulder_pitch_joint" type="revolute">
    <origin xyz="-0.0149999999998838 -0.0834906219829068 0.2865" rpy="0 0 0" />
    <parent link="torso_link" />
    <child link="right_shoulder_pitch_link" />
    <axis xyz="0 1 0" />
    <limit lower="-3.1416" upper="1.5708" effort="0" velocity="0" />
  </joint>
  <link name="right_shoulder_roll_link">
    <inertial>
      <origin xyz="0.0011333 -0.00054141 -0.0024787" rpy="0 0 0" />
      <mass value="0.2" />
      <inertia ixx="0.000111" ixy="-3.8745E-09" ixz="4.0005E-08" iyy="7.1762E-05" iyz="-1.8435E-06" izz="7.126E-05" />
    </inertial>
    <!-- <visual>
      <origin xyz="0 0 0" rpy="0 0 0" />
      <geometry>
        <mesh filename="meshes/right_shoulder_roll_link.STL" />
      </geometry>
      <material name="">
        <color rgba="1 1 1 1" />
      </material>
    </visual>
    <collision>
      <origin xyz="0 0 0" rpy="0 0 0" />
      <geometry>
        <mesh filename="meshes/right_shoulder_roll_link.STL" />
      </geometry>
    </collision> -->
    <collision>
      <origin xyz="0 0 0"/>
      <geometry>
          <sphere radius="0.025"/>
      </geometry>
    </collision>
  </link>
  <joint name="right_shoulder_roll_joint" type="revolute">
    <origin xyz="0 -0.07399527579835 0" rpy="0 0 0" />
    <parent link="right_shoulder_pitch_link" />
    <child link="right_shoulder_roll_link" />
    <axis xyz="1 0 0" />
    <limit lower="-2.0944" upper="0.1222" effort="0" velocity="0" />
  </joint>
  <link name="right_shoulder_yaw_link">
    <inertial>
      <origin xyz="0.0010112 -3.4168E-05 -0.096956" rpy="0 0 0" />
      <mass value="1.7" />
      <inertia ixx="0.0026061" ixy="-1.2821E-08" ixz="5.8541E-06" iyy="0.002525" iyz="7.7049E-06" izz="0.00054206" />
    </inertial>
    <!-- <visual>
      <origin xyz="0 0 0" rpy="0 0 0" />
      <geometry>
        <mesh filename="meshes/right_shoulder_yaw_link.STL" />
      </geometry>
      <material name="">
        <color rgba="1 1 1 1" />
      </material>
    </visual>
    <collision>
      <origin xyz="0 0 0" rpy="0 0 0" />
      <geometry>
        <mesh filename="meshes/right_shoulder_yaw_link.STL" />
      </geometry>
    </collision> -->
    <collision>
      <origin xyz="0 0 -0.07" rpy="3.1416 0 0"/>
      <geometry>
          <cylinder radius="0.030" length="0.13"/>
      </geometry>
    </collision>
  </link>
  <joint name="right_shoulder_yaw_joint" type="revolute">
    <origin xyz="0 -0.00256631230718973 -0.0369111569453834" rpy="-0.0693126999225212 0 0" />
    <parent link="right_shoulder_roll_link" />
    <child link="right_shoulder_yaw_link" />
    <axis xyz="0 0 1" />
    <limit lower="-0.7854" upper="0.7854" effort="0" velocity="0" />
  </joint>
  <link name="right_elbow_link">
    <inertial>
      <origin xyz="0.00058454 5.2562E-12 -0.0012698" rpy="0 0 0" />
      <mass value="0.6" />
      <inertia ixx="5.5486E-05" ixy="-1.6972E-14" ixz="4.5201E-08" iyy="8.3729E-05" iyz="-5.3251E-11" izz="5.3989E-05" />
    </inertial>
    <!-- <visual>
      <origin xyz="0 0 0" rpy="0 0 0" />
      <geometry>
        <mesh filename="meshes/right_elbow_link.STL" />
      </geometry>
      <material name="">
        <color rgba="1 1 1 1" />
      </material>
    </visual>
    <collision>
      <origin xyz="0 0 0" rpy="0 0 0" />
      <geometry>
        <mesh filename="meshes/right_elbow_link.STL" />
      </geometry>
    </collision> -->
    <collision>
      <origin xyz="0 0 0"/>
      <geometry>
          <sphere radius="0.03"/>
      </geometry>
    </collision>
  </link>
  <joint name="right_elbow_joint" type="revolute">
    <origin xyz="0 0 -0.193" rpy="0 0 0" />
    <parent link="right_shoulder_yaw_link" />
    <child link="right_elbow_link" />
    <axis xyz="0 1 0" />
    <limit lower="-0.5236" upper="1.5708" effort="0" velocity="0" />
  </joint>
  <link name="right_wrist_roll_link">
    <inertial>
      <origin xyz="0.09449 -0.0006287 -0.00030231" rpy="0 0 0" />
      <mass value="1.1" />
      <inertia ixx="0.00025229" ixy="1.5559E-05" ixz="-1.8369E-05" iyy="0.0018327" iyz="1.7002E-07" izz="0.0018096" />
    </inertial>
    <!-- <visual>
      <origin xyz="0 0 0" rpy="0 0 0" />
      <geometry>
        <mesh filename="meshes/right_wrist_roll_link.STL" />
      </geometry>
      <material name="">
        <color rgba="1 1 1 1" />
      </material>
    </visual>
    <collision>
      <origin xyz="0 0 0" rpy="0 0 0" />
      <geometry>
        <mesh filename="meshes/right_wrist_roll_link.STL" />
      </geometry>
    </collision> -->
    <collision>
      <origin xyz="0.1 0 0" rpy="0 1.57 0"/>
      <geometry>
          <cylinder radius="0.030" length="0.18"/>
      </geometry>
    </collision>
  </link>
  <joint name="right_wrist_roll_joint" type="revolute">
    <origin xyz="0.0319999999999996 0 0" rpy="0 0 0" />
    <parent link="right_elbow_link" />
    <child link="right_wrist_roll_link" />
    <axis xyz="1 0 0" />
    <limit lower="-0.7854" upper="0.7854" effort="0" velocity="0" />
  </joint>
  <link name="right_wrist_yaw_link">
    <inertial>
      <origin xyz="0.01075 -1.3678E-13 3.3307E-16" rpy="0 0 0" />
      <mass value="0.1" />
      <inertia ixx="2.0918E-06" ixy="7.3683E-20" ixz="9.9917E-22" iyy="3.7169E-06" iyz="-3.9969E-21" izz="3.7169E-06" />
    </inertial>
    <visual>
      <origin xyz="0 0 0" rpy="0 0 0" />
      <geometry>
        <mesh filename="meshes/right_wrist_yaw_link.STL" />
      </geometry>
      <material name="">
        <color rgba="1 1 1 1" />
      </material>
    </visual>
    <collision>
      <origin xyz="0 0 0" rpy="0 0 0" />
      <geometry>
        <mesh filename="meshes/right_wrist_yaw_link.STL" />
      </geometry>
    </collision>
  </link>
  <joint name="right_wrist_yaw_joint" type="fixed">
    <origin xyz="0.203 0 0" rpy="0 0 0" />
    <parent link="right_wrist_roll_link" />
    <child link="right_wrist_yaw_link" />
    <axis xyz="0 0 1" />
    <limit lower="-1.0472" upper="1.0472" effort="0" velocity="0" />
  </joint>
  <link name="right_wrist_pitch_link">
    <inertial>
      <origin xyz="0.063609 -0.00066189 0.0046223" rpy="0 0 0" />
      <mass value="0.6" />
      <inertia ixx="0.00020174" ixy="-1.8409E-05" ixz="-6.2672E-06" iyy="0.00055219" iyz="-3.2146E-05" izz="0.00044197" />
    </inertial>
    <visual>
      <origin xyz="0 0 0" rpy="0 0 0" />
      <geometry>
        <mesh filename="meshes/right_wrist_pitch_link.STL" />
      </geometry>
      <material name="">
        <color rgba="1 1 1 1" />
      </material>
    </visual>
    <collision>
      <origin xyz="0 0 0" rpy="0 0 0" />
      <geometry>
        <mesh filename="meshes/right_wrist_pitch_link.STL" />
      </geometry>
    </collision>
  </link>
  <joint name="right_wrist_pitch_joint" type="fixed">
    <origin xyz="0.0215000000000027 0 0" rpy="0 0 0" />
    <parent link="right_wrist_yaw_link" />
    <child link="right_wrist_pitch_link" />
    <axis xyz="0 1 0" />
    <limit lower="-0.5236" upper="0.5236" effort="0" velocity="0" />
  </joint>
</robot>