<mujoco model="X02">
  <compiler angle="radian" meshdir="./meshes/"/>
  <statistic meansize="0.177939" extent="1.9618" center="0.0465088 1.93584e-06 -0.21519"/>
  <asset>
    <texture type="skybox" builtin="gradient" width="128" height="128" rgb1="0.4 0.6 0.8" rgb2="0 0 0"/>
    <texture name="plane" type="2d" builtin="checker" rgb1="0.2 0.2 0.2" rgb2="0.3 0.3 0.3" width="512"
              height="512"/>
    <material name="plane" reflectance="0.0" texture="plane" texrepeat="1 1" texuniform="true"/>
    <mesh name="pelvis" file="pelvis.STL"/>
    <mesh name="left_hip_yaw_link" file="left_hip_yaw_link.STL"/>
    <mesh name="left_hip_roll_link" file="left_hip_roll_link.STL"/>
    <mesh name="left_hip_pitch_link" file="left_hip_pitch_link.STL"/>
    <mesh name="left_knee_link" file="left_knee_link.STL"/>
    <mesh name="left_ankle_pitch_link" file="left_ankle_pitch_link.STL"/>
    <mesh name="right_hip_yaw_link" file="right_hip_yaw_link.STL"/>
    <mesh name="right_hip_roll_link" file="right_hip_roll_link.STL"/>
    <mesh name="right_hip_pitch_link" file="right_hip_pitch_link.STL"/>
    <mesh name="right_knee_link" file="right_knee_link.STL"/>
    <mesh name="right_ankle_pitch_link" file="right_ankle_pitch_link.STL"/>
    <mesh name="waist_yaw_link" file="waist_yaw_link.STL"/>
    <mesh name="torso_link" file="torso_link.STL"/>
    <mesh name="logo_link" file="logo_link.STL"/>
    <mesh name="head_link" file="head_link.STL"/>
    <mesh name="left_shoulder_pitch_link" file="left_shoulder_pitch_link.STL"/>
    <mesh name="left_shoulder_roll_link" file="left_shoulder_roll_link.STL"/>
    <mesh name="left_shoulder_yaw_link" file="left_shoulder_yaw_link.STL"/>
    <mesh name="left_elbow_link" file="left_elbow_link.STL"/>
    <mesh name="left_wrist_roll_link" file="left_wrist_roll_link.STL"/>
    <mesh name="right_shoulder_pitch_link" file="right_shoulder_pitch_link.STL"/>
    <mesh name="right_shoulder_roll_link" file="right_shoulder_roll_link.STL"/>
    <mesh name="right_shoulder_yaw_link" file="right_shoulder_yaw_link.STL"/>
    <mesh name="right_elbow_link" file="right_elbow_link.STL"/>
    <mesh name="right_wrist_roll_link" file="right_wrist_roll_link.STL"/>
  </asset>
  <worldbody>
    <geom name="floor" pos="0.001 0 0" size="100 10 .125" type="plane" material="plane" condim="3"
          conaffinity="15" friction="0.6 0.6 0.001"/>
    <light mode="trackcom" pos="0 0 5" dir="0 0 -1"/>
    <body name="pelvis" pos="0 0 1.04">
      <inertial pos="-0.00324853 -2.87468e-06 0.21826" quat="0.999947 3.82205e-06 0.0102899 -2.32156e-05" mass="13.11" diaginertia="0.504265 0.480728 0.113235"/>
      <joint name="pelvis" type="free"/>
      <geom type="mesh" contype="0" conaffinity="0" group="1" density="0" rgba="0.45 0.45 0.45 1" mesh="pelvis"/>
      <geom type="mesh" rgba="0.45 0.45 0.45 1" mesh="pelvis"/>
      <site name="imu" pos="0 0 0"/>
      <geom pos="0 0 -0.1315" type="mesh" contype="0" conaffinity="0" group="1" density="0" rgba="1 1 1 1" mesh="waist_yaw_link"/>
      <geom pos="0 0 -0.1315" type="mesh" rgba="1 1 1 1" mesh="waist_yaw_link"/>
      <geom type="mesh" contype="0" conaffinity="0" group="1" density="0" rgba="1.43 1.43 1.43 1" mesh="torso_link"/>
      <geom type="mesh" rgba="1.43 1.43 1.43 1" mesh="torso_link"/>
      <geom type="mesh" contype="0" conaffinity="0" group="1" density="0" rgba="0 0 0 1" mesh="logo_link"/>
      <geom type="mesh" rgba="0 0 0 1" mesh="logo_link"/>
      <geom pos="-0.01 0 0.3575" type="mesh" contype="0" conaffinity="0" group="1" density="0" rgba="1 1 1 1" mesh="head_link"/>
      <geom pos="-0.01 0 0.3575" type="mesh" rgba="1 1 1 1" mesh="head_link"/>
      <body name="head" pos="0.01 0 0.55">
        <geom name="head" type="sphere" size=".0001" density="0"/>
      </body>
      <body name="left_hip_yaw_link" pos="0 0 -0.1315">
        <inertial pos="0 0.0271793 0.00194454" quat="0.509807 0.489996 -0.489996 0.509807" mass="0.841" diaginertia="0.00203399 0.00200206 0.000538133"/>
        <joint name="left_hip_yaw_joint" pos="0 0 0" axis="0 0 1" range="-0.785 0.785"/>
        <geom type="mesh" contype="0" conaffinity="0" group="1" density="0" rgba="0.41961 0.41961 0.41961 1" mesh="left_hip_yaw_link"/>
        <body name="left_hip_roll_link" pos="0 0.12 -0.001">
          <inertial pos="-0.034584 0.00017707 -0.071764" quat="0.68852 0.164795 0.159084 0.688095" mass="2.667" diaginertia="0.0112939 0.0106495 0.00649981"/>
          <joint name="left_hip_roll_joint" pos="0 0 0" axis="1 0 0" range="-0.349 0.534"/>
          <geom type="mesh" contype="0" conaffinity="0" group="1" density="0" rgba="0.41961 0.41961 0.41961 1" mesh="left_hip_roll_link"/>
          <geom type="mesh" rgba="0.41961 0.41961 0.41961 1" mesh="left_hip_roll_link"/>
          <body name="left_hip_pitch_link" pos="0 0 -0.11">
            <inertial pos="0.0082287 0 -0.167031" quat="0.706936 0.0155262 0.0155262 0.706936" mass="1.8" diaginertia="0.0177056 0.017016 0.00316021"/>
            <joint name="left_hip_pitch_joint" pos="0 0 0" axis="0 1 0" range="-2.094 0.534"/>
            <geom type="mesh" contype="0" conaffinity="0" group="1" density="0" rgba="1.43 1.43 1.43 1" mesh="left_hip_pitch_link"/>
            <geom type="mesh" rgba="1.43 1.43 1.43 1" mesh="left_hip_pitch_link"/>
            <body name="left_knee_link" pos="0 0 -0.35">
              <inertial pos="0.00111166 0 -0.146097" quat="0.707021 -0.0110178 -0.0110178 0.707021" mass="1.125" diaginertia="0.0117203 0.0115906 0.00120819"/>
              <joint name="left_knee_joint" pos="0 0 0" axis="0 1 0" range="0 2.269"/>
              <geom type="mesh" contype="0" conaffinity="0" group="1" density="0" rgba="1.43 1.43 1.43 1" mesh="left_knee_link"/>
              <geom type="mesh" rgba="1.43 1.43 1.43 1" mesh="left_knee_link"/>
              <body name="left_ankle_pitch_link" pos="0 0 -0.35">
                <inertial pos="0.0062069 0.00058964 -0.076695" quat="-0.00477942 0.696584 0.00509694 0.717441" mass="0.8" diaginertia="0.00355065 0.00328647 0.000388845"/>
                <joint name="left_ankle_pitch_joint" pos="0 0 0" axis="0 1 0" range="-1.047 1.047"/>
                <geom type="mesh" contype="0" conaffinity="0" group="1" density="0" rgba="0.45 0.45 0.45 1" mesh="left_ankle_pitch_link"/>
                <geom size="0.115 0.035 0.01" pos="0.01 0 -0.075" type="box" rgba="0.45 0.45 0.45 1"/>
                <geom size="0.005" pos="-0.118 0 -0.095" rgba="0.45 0.45 0.45 1"/>
                <geom size="0.005" pos="-0.075 0.039 -0.095" rgba="0.45 0.45 0.45 1"/>
                <geom size="0.005" pos="-0.075 -0.039 -0.095" rgba="0.45 0.45 0.45 1"/>
                <geom size="0.005" pos="0.08 0.047 -0.095" rgba="0.45 0.45 0.45 1"/>
                <geom size="0.005" pos="0.08 -0.047 -0.095" rgba="0.45 0.45 0.45 1"/>
                <geom size="0.005" pos="0.15 -0.01 -0.095" rgba="0.45 0.45 0.45 1"/>
                <body name="left_toe_link" pos="0.15 0.0 -0.05">
                    <geom name="left_toe_link" type="box" size="0.025 0.025 0.003" pos="-0.05 0.0 -0.025" contype="1" conaffinity="1"/>
                </body>
              </body>
            </body>
          </body>
        </body>
      </body>
      <body name="right_hip_yaw_link" pos="0 0 -0.1315">
        <inertial pos="0 -0.050494 0.006108" quat="0.722974 0.690875 0 0" mass="0.947" diaginertia="0.00267262 0.00231924 0.000763015"/>
        <joint name="right_hip_yaw_joint" pos="0 0 0" axis="0 0 1" range="-0.785 0.785"/>
        <geom type="mesh" contype="0" conaffinity="0" group="1" density="0" rgba="0.41961 0.41961 0.41961 1" mesh="right_hip_yaw_link"/>
        <geom type="mesh" rgba="0.41961 0.41961 0.41961 1" mesh="right_hip_yaw_link"/>
        <body name="right_hip_roll_link" pos="0 -0.12 -0.001">
          <inertial pos="-0.034584 -0.00017759 -0.071763" quat="0.688098 0.159077 0.164778 0.688523" mass="2.667" diaginertia="0.0112941 0.0106496 0.0064998"/>
          <joint name="right_hip_roll_joint" pos="0 0 0" axis="1 0 0" range="-0.534 0.349"/>
          <geom type="mesh" contype="0" conaffinity="0" group="1" density="0" rgba="0.41961 0.41961 0.41961 1" mesh="right_hip_roll_link"/>
          <geom type="mesh" rgba="0.41961 0.41961 0.41961 1" mesh="right_hip_roll_link"/>
          <body name="right_hip_pitch_link" pos="0 0 -0.11">
            <inertial pos="0.0082287 0 -0.167031" quat="0.706937 0.0155252 0.0155272 0.706935" mass="1.8" diaginertia="0.0177056 0.017016 0.0031602"/>
            <joint name="right_hip_pitch_joint" pos="0 0 0" axis="0 1 0" range="-2.094 0.534"/>
            <geom type="mesh" contype="0" conaffinity="0" group="1" density="0" rgba="1.43 1.43 1.43 1" mesh="right_hip_pitch_link"/>
            <geom type="mesh" rgba="1.43 1.43 1.43 1" mesh="right_hip_pitch_link"/>
            <body name="right_knee_link" pos="0 0 -0.35">
              <inertial pos="0.00111164 0 -0.146097" quat="0.707021 -0.0110174 -0.0110174 0.707021" mass="1.125" diaginertia="0.0117203 0.0115906 0.00120819"/>
              <joint name="right_knee_joint" pos="0 0 0" axis="0 1 0" range="0 2.269"/>
              <geom type="mesh" contype="0" conaffinity="0" group="1" density="0" rgba="1.43 1.43 1.43 1" mesh="right_knee_link"/>
              <geom type="mesh" rgba="1.43 1.43 1.43 1" mesh="right_knee_link"/>
              <body name="right_ankle_pitch_link" pos="0 0 -0.35" quat="1 0 -0.00062945 0">
                <inertial pos="0.0062069 -0.00058964 -0.076695" quat="-0.00477942 0.696584 0.00509694 0.717441" mass="0.8" diaginertia="0.00355065 0.00328647 0.000388845"/>
                <joint name="right_ankle_pitch_joint" pos="0 0 0" axis="0 1 0" range="-1.047 1.047"/>
                <geom type="mesh" contype="0" conaffinity="0" group="1" density="0" rgba="0.45 0.45 0.45 1" mesh="right_ankle_pitch_link"/>
                <geom size="0.115 0.035 0.01" pos="0.01 0 -0.075" type="box" rgba="0.45 0.45 0.45 1"/>
                <geom size="0.005" pos="-0.118 0 -0.095" rgba="0.45 0.45 0.45 1"/>
                <geom size="0.005" pos="-0.075 0.039 -0.095" rgba="0.45 0.45 0.45 1"/>
                <geom size="0.005" pos="-0.075 -0.039 -0.095" rgba="0.45 0.45 0.45 1"/>
                <geom size="0.005" pos="0.08 0.047 -0.095" rgba="0.45 0.45 0.45 1"/>
                <geom size="0.005" pos="0.08 -0.047 -0.095" rgba="0.45 0.45 0.45 1"/>
                <geom size="0.005" pos="0.15 0.01 -0.095" rgba="0.45 0.45 0.45 1"/>
                <body name="right_toe_link" pos="0.15 0.0 -0.075">
                    <geom name="right_toe_link" type="box" size="0.025 0.025 0.003" pos="-0.05 0.0 -0.025" contype="1" conaffinity="1"/>
                </body>
              </body>
            </body>
          </body>
        </body>
      </body>
      <body name="left_shoulder_pitch_link" pos="-0.01 0.13365 0.31135" quat="0.996195 0.0871543 0 0">
        <inertial pos="0 0.0291327 0" quat="0 0.707107 0 0.707107" mass="0.276" diaginertia="0.00033854 0.00021249 0.00019627"/>
        <joint name="left_shoulder_pitch_joint" pos="0 0 0" axis="0 1 0" range="-2.749 2.749"/>
        <geom type="mesh" contype="0" conaffinity="0" group="1" density="0" rgba="0.419608 0.419608 0.419608 1" mesh="left_shoulder_pitch_link"/>
        <geom type="mesh" rgba="0.419608 0.419608 0.419608 1" mesh="left_shoulder_pitch_link"/>
        <body name="left_shoulder_roll_link" pos="0 0.0588 0" quat="0.996195 -0.0871543 0 0">
          <inertial pos="0.00013265 0.00797093 -0.0452124" quat="0.996194 0.0871559 -0.00108264 -8.46243e-05" mass="1.126" diaginertia="0.00147896 0.00143617 0.000604058"/>
          <joint name="left_shoulder_roll_joint" pos="0 0 0" axis="1 0 0" range="-0.175 2.653"/>
          <geom type="mesh" contype="0" conaffinity="0" group="1" density="0" rgba="1.43 1.43 1.43 1" mesh="left_shoulder_roll_link"/>
          <geom type="mesh" rgba="1.43 1.43 1.43 1" mesh="left_shoulder_roll_link"/>
          <body name="left_shoulder_yaw_link" pos="0 0.018928 -0.10734" quat="0.996195 0.0871543 0 0">
            <inertial pos="-0.00093704 0 -0.0773534" quat="0.999861 -9.26162e-06 0.0166815 9.57554e-06" mass="0.896" diaginertia="0.00233046 0.00227734 0.00068588"/>
            <joint name="left_shoulder_yaw_joint" pos="0 0 0" axis="0 0 1" range="-2.618 2.618"/>
            <geom type="mesh" contype="0" conaffinity="0" group="1" density="0" rgba="1.43 1.43 1.43 1" mesh="left_shoulder_yaw_link"/>
            <geom type="mesh" rgba="1.43 1.43 1.43 1" mesh="left_shoulder_yaw_link"/>
            <body name="left_elbow_link" pos="0.01 0 -0.151">
              <inertial pos="0.094558 -1.42e-06 -0.010969" quat="2.10949e-05 0.726688 1.11405e-05 0.686968" mass="0.576" diaginertia="0.00169291 0.00166805 0.000367391"/>
              <joint name="left_elbow_joint" pos="0 0 0" axis="0 1 0" range="-0.873 1.571"/>
              <geom type="mesh" contype="0" conaffinity="0" group="1" density="0" rgba="1.43 1.43 1.43 1" mesh="left_elbow_link"/>
              <geom type="mesh" rgba="1.43 1.43 1.43 1" mesh="left_elbow_link"/>
              <body name="left_wrist_roll_link" pos="0.201 0 -0.01" quat="0.996195 -0.0871543 0 0">
                <inertial pos="0.075054 -0.00332326 0.00545989" quat="0.367477 0.623051 0.297071 0.623311" mass="0.692" diaginertia="0.000624386 0.00049968 0.000198465"/>
                <joint name="left_wrist_roll_joint" pos="0 0 0" axis="1 0 0" range="-2.662 2.662"/>
                <geom type="mesh" contype="0" conaffinity="0" group="1" density="0" rgba="0.419608 0.419608 0.419608 1" mesh="left_wrist_roll_link"/>
                <geom type="mesh" rgba="0.419608 0.419608 0.419608 1" mesh="left_wrist_roll_link"/>
              </body>
            </body>
          </body>
        </body>
      </body>
      <body name="right_shoulder_pitch_link" pos="-0.01 -0.13365 0.31135" quat="0.996195 -0.0871543 0 0">
        <inertial pos="0 -0.0291327 0" quat="0 0.707107 0 0.707107" mass="0.276" diaginertia="0.00033854 0.00021249 0.00019627"/>
        <joint name="right_shoulder_pitch_joint" pos="0 0 0" axis="0 1 0" range="-2.749 2.749"/>
        <geom type="mesh" contype="0" conaffinity="0" group="1" density="0" rgba="0.419608 0.419608 0.419608 1" mesh="right_shoulder_pitch_link"/>
        <geom type="mesh" rgba="0.419608 0.419608 0.419608 1" mesh="right_shoulder_pitch_link"/>
        <body name="right_shoulder_roll_link" pos="0 -0.0588 0" quat="0.996195 0.0871543 0 0">
          <inertial pos="0.000132994 -0.00797311 -0.0452117" quat="0.996194 -0.0871554 -0.00108071 0.00011147" mass="1.126" diaginertia="0.00147896 0.00143616 0.000604056"/>
          <joint name="right_shoulder_roll_joint" pos="0 0 0" axis="1 0 0" range="-2.653 0.175"/>
          <geom type="mesh" contype="0" conaffinity="0" group="1" density="0" rgba="1.43 1.43 1.43 1" mesh="right_shoulder_roll_link"/>
          <geom type="mesh" rgba="1.43 1.43 1.43 1" mesh="right_shoulder_roll_link"/>
          <body name="right_shoulder_yaw_link" pos="0 -0.018928 -0.10734" quat="0.996195 -0.0871543 0 0">
            <inertial pos="-0.0009376 0 -0.0773538" quat="0.999861 4.50062e-06 0.0166784 -0.000100443" mass="0.896" diaginertia="0.00233047 0.00227735 0.000685881"/>
            <joint name="right_shoulder_yaw_joint" pos="0 0 0" axis="0 0 1" range="-2.618 2.618"/>
            <geom type="mesh" contype="0" conaffinity="0" group="1" density="0" rgba="1.43 1.43 1.43 1" mesh="right_shoulder_yaw_link"/>
            <geom type="mesh" rgba="1.43 1.43 1.43 1" mesh="right_shoulder_yaw_link"/>
            <body name="right_elbow_link" pos="0.01 0 -0.151">
              <inertial pos="0.0945565 0 -0.0109687" quat="0 0.726686 0 0.68697" mass="0.576" diaginertia="0.00169287 0.00166798 0.000367392"/>
              <joint name="right_elbow_joint" pos="0 0 0" axis="0 1 0" range="-0.873 1.571"/>
              <geom type="mesh" contype="0" conaffinity="0" group="1" density="0" rgba="1.43 1.43 1.43 1" mesh="right_elbow_link"/>
              <geom type="mesh" rgba="1.43 1.43 1.43 1" mesh="right_elbow_link"/>
              <body name="right_wrist_roll_link" pos="0.201 0 -0.01" quat="0.996195 0.0871543 0 0">
                <inertial pos="0.0750546 0.00332421 0.00545739" quat="0.623317 0.297058 0.623056 0.36747" mass="0.692" diaginertia="0.000624397 0.000499679 0.000198479"/>
                <joint name="right_wrist_roll_joint" pos="0 0 0" axis="1 0 0" range="-2.662 2.662"/>
                <geom type="mesh" contype="0" conaffinity="0" group="1" density="0" rgba="0.419608 0.419608 0.419608 1" mesh="right_wrist_roll_link"/>
                <geom type="mesh" rgba="0.419608 0.419608 0.419608 1" mesh="right_wrist_roll_link"/>
                <geom name="hand_axis_x" type="capsule" fromto="0 0 0 0.1 0 0" size="0.002" rgba="1 0 0 1"/>
                <geom name="hand_axis_y" type="capsule" fromto="0 0 0 0 0.1 0" size="0.002" rgba="0 1 0 1"/>
                <geom name="hand_axis_z" type="capsule" fromto="0 0 0 0 0 0.1" size="0.002" rgba="0 0 1 1"/>
              </body>
            </body>
          </body>
        </body>
      </body>
    </body>
  </worldbody>

  <actuator>
    <motor name="left_hip_yaw_joint" joint="left_hip_yaw_joint"/>
    <motor name="left_hip_roll_joint" joint="left_hip_roll_joint"/>
    <motor name="left_hip_pitch_joint" joint="left_hip_pitch_joint"/>
    <motor name="left_knee_joint" joint="left_knee_joint"/>
    <motor name="left_ankle_pitch_joint" joint="left_ankle_pitch_joint"/>
    <motor name="right_hip_yaw_joint" joint="right_hip_yaw_joint"/>
    <motor name="right_hip_roll_joint" joint="right_hip_roll_joint"/>
    <motor name="right_hip_pitch_joint" joint="right_hip_pitch_joint"/>
    <motor name="right_knee_joint" joint="right_knee_joint"/>
    <motor name="right_ankle_pitch_joint" joint="right_ankle_pitch_joint"/>
    <motor name="left_shoulder_pitch_joint" joint="left_shoulder_pitch_joint"/>
    <motor name="left_shoulder_roll_joint" joint="left_shoulder_roll_joint"/>
    <motor name="left_shoulder_yaw_joint" joint="left_shoulder_yaw_joint"/>
    <motor name="left_elbow_joint" joint="left_elbow_joint"/>
    <motor name="left_wrist_roll_joint" joint="left_wrist_roll_joint"/>
    <motor name="right_shoulder_pitch_joint" joint="right_shoulder_pitch_joint"/>
    <motor name="right_shoulder_roll_joint" joint="right_shoulder_roll_joint"/>
    <motor name="right_shoulder_yaw_joint" joint="right_shoulder_yaw_joint"/>
    <motor name="right_elbow_joint" joint="right_elbow_joint"/>
    <motor name="right_wrist_roll_joint" joint="right_wrist_roll_joint"/>
  </actuator>

  <sensor>
        <framequat name="BodyQuat" objtype="site" objname="imu"/>
  </sensor>
</mujoco>
