<?xml version="1.0" encoding="utf-8"?>
<!-- This URDF was automatically created by SolidWorks to URDF Exporter! Originally created by Stephen Brawner (brawner@gmail.com) 
     Commit Version: 1.6.0-4-g7f85cfe  Build Version: 1.6.7995.38578
     For more information, please see http://wiki.ros.org/sw_urdf_exporter -->
<robot name="x3">

  <mujoco>
    <compiler meshdir="./meshes" discardvisual="false" />
  </mujoco>

  <!-- <link name="world"></link>
  <joint name="pelvis_link" type="floating">
    <parent link="world" />
    <child link="pelvis_link" />
  </joint> -->

  <link name="pelvis_link">
    <inertial>
      <origin xyz="0 0.0002374 0.08138805" rpy="0 0 0" />
      <mass value="2.4" />
      <inertia ixx="0.01183793" ixy="-0.00000035" ixz="0.00000000" iyy="0.01469122" iyz="0.00000227" izz="0.01600167" />
    </inertial>
    <visual>
      <origin xyz="0 0 0" rpy="0 0 0" />
      <geometry>
        <mesh filename="meshes/pelvis_link.STL" />
      </geometry>
      <material name="">
        <color rgba="1 1 1 1" />
      </material>
    </visual>
    <!-- <collision>
      <origin xyz="0 0 0" rpy="0 0 0" />
      <geometry>
        <mesh filename="meshes/pelvis_link.STL" />
      </geometry>
    </collision> -->
  </link>
  <link name="L_hip_pitch_link">
    <inertial>
      <origin xyz="0 -0.00129733 0.00058752" rpy="0 0 0" />
      <mass value="0.35" />
      <inertia ixx="0.00077282" ixy="0.00000000" ixz="0.00000000" iyy="0.00090761" iyz="0.00000636" izz="0.00091467" />
    </inertial>
    <visual>
      <origin xyz="0 0 0" rpy="0 0 0" />
      <geometry>
        <mesh filename="meshes/L_hip_pitch_link.STL" />
      </geometry>
      <material name="">
        <color rgba="0.41961 0.41961 0.41961 1" />
      </material>
    </visual>
    <collision>
      <origin xyz="0 0 0" rpy="0 0 0" />
      <geometry>
        <mesh filename="meshes/L_hip_pitch_link.STL" />
      </geometry>
    </collision>
  </link>
  <joint name="L_hip_pitch" type="revolute">
    <origin xyz="0 0.071 0.0419" rpy="0 0 0" />
    <parent link="pelvis_link" />
    <child link="L_hip_pitch_link" />
    <axis xyz="0 -1 0" />
    <limit lower="-0.8727" upper="1.7453" effort="72" velocity="117.5" />
  </joint>
  <link name="L_hip_roll_link">
    <inertial>
      <origin xyz="0 0.04078379 -0.09187673" rpy="0 0 0" />
      <mass value="3.2" />
      <inertia ixx="0.01851882" ixy="0.00000000" ixz="-0.00000001" iyy="0.01634553" iyz="-0.00289271" izz="0.00663237" />
    </inertial>
    <visual>
      <origin xyz="0 0 0" rpy="0 0 0" />
      <geometry>
        <mesh filename="meshes/L_hip_roll_link.STL" />
      </geometry>
      <material name="">
        <color rgba="1 1 1 1" />
      </material>
    </visual>
    <collision>
      <origin xyz="0 0 0" rpy="0 0 0" />
      <geometry>
        <mesh filename="meshes/L_hip_roll_link.STL" />
      </geometry>
    </collision>
  </link>
  <joint name="L_hip_roll" type="revolute">
    <origin xyz="0 0 0" rpy="0 0 0" />
    <parent link="L_hip_pitch_link" />
    <child link="L_hip_roll_link" />
    <axis xyz="1 0 0" />
    <limit lower="-0.1309" upper="1.11" effort="36" velocity="235" />
  </joint>
  <link name="L_hip_yaw_link">
    <inertial>
      <origin xyz="0.00421444 0.00000785 -0.19916050" rpy="0 0 0" />
      <mass value="1.7" />
      <inertia ixx="0.01070579" ixy="0.00000152" ixz="-0.00075783" iyy="0.01061119" iyz="0.00000095" izz="0.00385510" />
    </inertial>
    <visual>
      <origin xyz="0 0 0" rpy="0 0 0" />
      <geometry>
        <mesh filename="meshes/L_hip_yaw_link.STL" />
      </geometry>
      <material name="">
        <color rgba="1 1 1 1" />
      </material>
    </visual>
    <collision>
      <origin xyz="0 0 0" rpy="0 0 0" />
      <geometry>
        <mesh filename="meshes/L_hip_yaw_link.STL" />
      </geometry>
    </collision>
  </link>
  <joint name="L_hip_yaw" type="revolute">
    <origin xyz="0 0.049 -0.043" rpy="0 0 0" />
    <parent link="L_hip_roll_link" />
    <child link="L_hip_yaw_link" />
    <axis xyz="0 0 1" />
    <limit lower="-0.7854" upper="0.7854" effort="24" velocity="37" />
  </joint>
  <link name="L_hip_yaw_black_link">
    <inertial>
      <origin xyz="0.010882 8.8917E-06 -0.34221" rpy="0 0 0" />
      <mass value="0.01" />
      <inertia ixx="0.00049307" ixy="1.8407E-08" ixz="0.00012312" iyy="0.00053872" iyz="-8.6888E-08" izz="0.00032966" />
    </inertial>
    <visual>
      <origin xyz="0 0 0" rpy="0 0 0" />
      <geometry>
        <mesh filename="meshes/L_hip_yaw_black_link.STL" />
      </geometry>
      <material name="">
        <color rgba="0.41176 0.41176 0.41176 1" />
      </material>
    </visual>
    <!-- <collision>
      <origin xyz="0 0 0" rpy="0 0 0" />
      <geometry>
        <mesh filename="meshes/L_hip_yaw_black_link.STL" />
      </geometry>
    </collision> -->
  </link>
  <joint name="L_hip_yaw_black" type="fixed">
    <origin xyz="0 0 0" rpy="0 0 0" />
    <parent link="L_hip_yaw_link" />
    <child link="L_hip_yaw_black_link" />
    <axis xyz="0 0 0" />
  </joint>
  <link name="L_knee_pitch_black_link">
    <inertial>
      <origin xyz="0.0036108 -2.1226E-06 -0.1102" rpy="0 0 0" />
      <mass value="0.01" />
      <inertia ixx="0.0145" ixy="1.7116E-08" ixz="-0.00044634" iyy="0.014482" iyz="8.0516E-08" izz="0.00098127" />
    </inertial>
    <visual>
      <origin xyz="0 0 0" rpy="0 0 0" />
      <geometry>
        <mesh filename="meshes/L_knee_pitch_black_link.STL" />
      </geometry>
      <material name="">
        <color rgba="0.41176 0.41176 0.41176 1" />
      </material>
    </visual>
    <!-- <collision>
      <origin xyz="0 0 0" rpy="0 0 0" />
      <geometry>
        <mesh filename="meshes/L_knee_pitch_black_link.STL" />
      </geometry>
    </collision> -->
  </link>
  <!-- <joint name="L_knee_pitch_black" type="fixed">
    <origin xyz="0 0 -0.357" rpy="0 0 0" />
    <parent link="L_hip_yaw_black_link" />
    <child link="L_knee_pitch_black_link" />
    <axis xyz="0 0 0" />
  </joint> -->
  <joint name="L_knee_pitch_black" type="fixed">
    <origin xyz="0 0 0" rpy="0 0 0" />
    <parent link="L_knee_pitch_link" />
    <child link="L_knee_pitch_black_link" />
    <axis xyz="0 0 0" />
  </joint>
  <link name="L_knee_pitch_link">
    <inertial>
      <origin xyz="0.00459772 0 -0.22342401" rpy="0 0 0" />
      <mass value="1.2" />
      <inertia ixx="0.01015001" ixy="-0.00000002" ixz="0.00082886" iyy="0.01039687" iyz="0.00000003" izz="0.00150910" />
    </inertial>
    <visual>
      <origin xyz="0 0 0" rpy="0 0 0" />
      <geometry>
        <mesh filename="meshes/L_knee_pitch_link.STL" />
      </geometry>
      <material name="">
        <color rgba="1 1 1 1" />
      </material>
    </visual>
    <collision>
      <origin xyz="0 0 0" rpy="0 0 0" />
      <geometry>
        <mesh filename="meshes/L_knee_pitch_link.STL" />
      </geometry>
    </collision>
  </link>
  <!-- <joint name="L_knee_pitch" type="revolute">
    <origin xyz="0 0 0" rpy="0 0 0" />
    <parent link="L_knee_pitch_black_link" />
    <child link="L_knee_pitch_link" />
    <axis xyz="0 -1 0" />
    <limit lower="-2.3562" upper="0" effort="93.6" velocity="90" />
  </joint> -->
  <joint name="L_knee_pitch" type="revolute">
    <origin xyz="0 0 -0.357" rpy="0 0 0" />
    <parent link="L_hip_yaw_black_link" />
    <child link="L_knee_pitch_link" />
    <axis xyz="0 -1 0" />
    <limit lower="-2.3562" upper="0" effort="93.6" velocity="90" />
  </joint>
  <link name="L_ankle_pitch_link">
    <inertial>
      <origin xyz="0 0 -0.03720405" rpy="0 0 0" />
      <mass value="0.2" />
      <inertia ixx="0.00020542" ixy="0.0000000" ixz="0.00000000" iyy="0.00022529" iyz="0.00000000" izz="0.00007465" />
    </inertial>
    <visual>
      <origin xyz="0 0 0" rpy="0 0 0" />
      <geometry>
        <mesh filename="meshes/L_ankle_pitch_link.STL" />
      </geometry>
      <material name="">
        <color rgba="0.62745 0.62745 0.62745 1" />
      </material>
    </visual>
    <collision>
      <origin xyz="0 0 0" rpy="0 0 0" />
      <geometry>
        <mesh filename="meshes/L_ankle_pitch_link.STL" />
      </geometry>
    </collision>
  </link>
  <joint name="L_ankle_pitch" type="revolute">
    <origin xyz="0 0 -0.43" rpy="0 0 0" />
    <parent link="L_knee_pitch_link" />
    <child link="L_ankle_pitch_link" />
    <axis xyz="0 -1 0" />
    <limit lower="-1.309" upper="1.309" effort="64.8" velocity="130" />
  </joint>
  <link name="L_ankle_roll_link">
    <inertial>
      <origin xyz="0.04505385 0.00001354 -0.02342946" rpy="0 0 0" />
      <mass value="0.6" />
      <inertia ixx="0.00041777" ixy="-0.00000006" ixz="-0.00009663" iyy="0.00376485" iyz="0.00000000" izz="0.00406581" />
    </inertial>
    <visual>
      <origin xyz="0 0 0" rpy="0 0 0" />
      <geometry>
        <mesh filename="meshes/L_ankle_roll_link.STL" />
      </geometry>
      <material name="">
        <color rgba="0.62745 0.62745 0.62745 1" />
      </material>
    </visual>
    <!-- <collision>
      <origin xyz="0 0 0" rpy="0 0 0" />
      <geometry>
        <mesh filename="meshes/L_ankle_roll_link.STL" />
      </geometry>
    </collision> -->
<!--    <collision>-->
<!--      <origin xyz="-0.066 0.03 -0.034" rpy="0 0 0"/>-->
<!--      <geometry>-->
<!--        <sphere radius="0.005"/>-->
<!--      </geometry>-->
<!--    </collision>-->
<!--    <collision>-->
<!--      <origin xyz="-0.066 -0.03 -0.034" rpy="0 0 0"/>-->
<!--      <geometry>-->
<!--        <sphere radius="0.005"/>-->
<!--      </geometry>-->
<!--    </collision>-->
<!--    <collision>-->
<!--      <origin xyz="0.16 0.035 -0.034" rpy="0 0 0"/>-->
<!--      <geometry>-->
<!--        <sphere radius="0.005"/>-->
<!--      </geometry>-->
<!--    </collision>-->
<!--    <collision>-->
<!--      <origin xyz="0.16 -0.035 -0.034" rpy="0 0 0"/>-->
<!--      <geometry>-->
<!--        <sphere radius="0.005"/>-->
<!--      </geometry>-->
<!--    </collision>-->
<!--    <collision>-->
<!--      <origin xyz="0.042 0.0 -0.0335" rpy="0 0 0"/>-->
<!--      <geometry>-->
<!--        <box size="0.2 0.05 0.01"/>-->
<!--      </geometry>-->
<!--    </collision>-->
    <collision> <origin xyz="0.04 0.0 0.00" rpy="0 0 0"/> <geometry> <box size="0.20 0.06 0.10"/> </geometry> </collision>
    <collision> <origin xyz="-0.09 -0.0   -0.0340" rpy="0 0 0"/> <geometry> <sphere radius="0.005"/> </geometry> </collision>
    <collision> <origin xyz=" 0.18 -0.0   -0.0340" rpy="0 0 0"/> <geometry> <sphere radius="0.005"/> </geometry> </collision>
    <collision> <origin xyz=" 0.12 -0.046 -0.0340" rpy="0 0 0"/> <geometry> <sphere radius="0.005"/> </geometry> </collision>
    <collision> <origin xyz=" 0.12  0.046 -0.0340" rpy="0 0 0"/> <geometry> <sphere radius="0.005"/> </geometry> </collision>
    <collision> <origin xyz="-0.03  0.033 -0.0340" rpy="0 0 0"/> <geometry> <sphere radius="0.005"/> </geometry> </collision>
    <collision> <origin xyz="-0.03 -0.033 -0.0340" rpy="0 0 0"/> <geometry> <sphere radius="0.005"/> </geometry> </collision>
  </link>
  <joint name="L_ankle_roll" type="revolute">
    <origin xyz="0 0 -0.058" rpy="0 0 0" />
    <parent link="L_ankle_pitch_link" />
    <child link="L_ankle_roll_link" />
    <axis xyz="1 0 0" />
    <limit lower="-0.5236" upper="0.5236" effort="7.7" velocity="20" />
  </joint>
  <link name="L_ankle_roll_white_link">
    <inertial>
      <origin xyz="0.052694 -9.4965E-08 0.0076216" rpy="0 0 0" />
      <mass value="0.01" />
      <inertia ixx="0.00038883" ixy="-2.5213E-09" ixz="0.00022024" iyy="0.0030036" iyz="1.5905E-09" izz="0.0031991" />
    </inertial>
    <visual>
      <origin xyz="0 0 0" rpy="0 0 0" />
      <geometry>
        <mesh filename="meshes/L_ankle_roll_white_link.STL" />
      </geometry>
      <material name="">
        <color rgba="1 1 1 1" />
      </material>
    </visual>
    <!-- <collision>
      <origin xyz="0 0 0" rpy="0 0 0" />
      <geometry>
        <mesh filename="meshes/L_ankle_roll_white_link.STL" />
      </geometry>
    </collision> -->
  </link>
  <joint name="L_ankle_roll_white" type="fixed">
    <origin xyz="0 0 0" rpy="0 0 0" />
    <parent link="L_ankle_roll_link" />
    <child link="L_ankle_roll_white_link" />
    <axis xyz="0 0 0" />
  </joint>
  <link name="R_hip_pitch_link">
    <inertial>
      <origin xyz="0 -0.00129733 0.00058752" rpy="0 0 0" />
      <mass value="0.35" />
      <inertia ixx="0.00077282" ixy="-0.00000000" ixz="0.00000000" iyy="0.00090761" iyz="-0.00000636" izz="0.00091467" />
    </inertial>
    <visual>
      <origin xyz="0 0 0" rpy="0 0 0" />
      <geometry>
        <mesh filename="meshes/R_hip_pitch_link.STL" />
      </geometry>
      <material name="">
        <color rgba="0.41961 0.41961 0.41961 1" />
      </material>
    </visual>
    <collision>
      <origin xyz="0 0 0" rpy="0 0 0" />
      <geometry>
        <mesh filename="meshes/R_hip_pitch_link.STL" />
      </geometry>
    </collision>
  </link>
  <joint name="R_hip_pitch" type="revolute">
    <origin xyz="0 -0.071 0.0419" rpy="0 0 0" />
    <parent link="pelvis_link" />
    <child link="R_hip_pitch_link" />
    <axis xyz="0 -1 0" />
    <limit lower="-0.8727" upper="1.7453" effort="72" velocity="117.5" />
  </joint>
  <link name="R_hip_roll_link">
    <inertial>
      <origin xyz="0 -0.04078345 -0.09187642" rpy="0 0 0" />
      <mass value="3.2" />
      <inertia ixx="0.01851882" ixy="-0.00000000" ixz="0.00000001" iyy="0.01634553" iyz="0.00289271" izz="0.00663237" />
    </inertial>
    <visual>
      <origin xyz="0 0 0" rpy="0 0 0" />
      <geometry>
        <mesh filename="meshes/R_hip_roll_link.STL" />
      </geometry>
      <material name="">
        <color rgba="1 1 1 1" />
      </material>
    </visual>
    <collision>
      <origin xyz="0 0 0" rpy="0 0 0" />
      <geometry>
        <mesh filename="meshes/R_hip_roll_link.STL" />
      </geometry>
    </collision>
  </link>
  <joint name="R_hip_roll" type="revolute">
    <origin xyz="0 0 0" rpy="0 0 0" />
    <parent link="R_hip_pitch_link" />
    <child link="R_hip_roll_link" />
    <axis xyz="-1 0 0" />
    <limit lower="-0.1309" upper="1.11" effort="36" velocity="235" />
  </joint>
  <link name="R_hip_yaw_link">
    <inertial>
      <origin xyz="0.00421444 0.00000785 -0.19916050" rpy="0 0 0" />
      <mass value="1.7" />
      <inertia ixx="0.01070579" ixy="-0.00000152" ixz="-0.00075783" iyy="0.01061119" iyz="-0.00000095" izz="0.00385510" />
    </inertial>
    <visual>
      <origin xyz="0 0 0" rpy="0 0 0" />
      <geometry>
        <mesh filename="meshes/R_hip_yaw_link.STL" />
      </geometry>
      <material name="">
        <color rgba="1 1 1 1" />
      </material>
    </visual>
    <collision>
      <origin xyz="0 0 0" rpy="0 0 0" />
      <geometry>
        <mesh filename="meshes/R_hip_yaw_link.STL" />
      </geometry>
    </collision>
  </link>
  <joint name="R_hip_yaw" type="revolute">
    <origin xyz="0 -0.049 -0.043" rpy="0 0 0" />
    <parent link="R_hip_roll_link" />
    <child link="R_hip_yaw_link" />
    <axis xyz="0 0 -1" />
    <limit lower="-0.7854" upper="0.7854" effort="24" velocity="37" />
  </joint>
  <link name="R_hip_yaw_black_link">
    <inertial>
      <origin xyz="0.010883 4.3825E-07 -0.34223" rpy="0 0 0" />
      <mass value="0.05" />
      <inertia ixx="0.00049284" ixy="-1.0446E-08" ixz="0.0001231" iyy="0.00053857" iyz="-2.0743E-08" izz="0.0003296" />
    </inertial>
    <visual>
      <origin xyz="0 0 0" rpy="0 0 0" />
      <geometry>
        <mesh filename="meshes/R_hip_yaw_black_link.STL" />
      </geometry>
      <material name="">
        <color rgba="0.41176 0.41176 0.41176 1" />
      </material>
    </visual>
    <!-- <collision>
      <origin xyz="0 0 0" rpy="0 0 0" />
      <geometry>
        <mesh filename="meshes/R_hip_yaw_black_link.STL" />
      </geometry>
    </collision> -->
  </link>
  <joint name="R_hip_yaw_black" type="fixed">
    <origin xyz="0 0 0" rpy="0 0 0" />
    <parent link="R_hip_yaw_link" />
    <child link="R_hip_yaw_black_link" />
    <axis xyz="0 0 0" />
  </joint>
  <link name="R_knee_pitch_black_link">
    <inertial>
      <origin xyz="0.0036099 -1.2526E-06 -0.1102" rpy="0 0 0" />
      <mass value="0.05" />
      <inertia ixx="0.014499" ixy="-5.0793E-08" ixz="-0.00044615" iyy="0.014481" iyz="-1.122E-07" izz="0.00098043" />
    </inertial>
    <visual>
      <origin xyz="0 0 0" rpy="0 0 0" />
      <geometry>
        <mesh filename="meshes/R_knee_pitch_black_link.STL" />
      </geometry>
      <material name="">
        <color rgba="0.41176 0.41176 0.41176 1" />
      </material>
    </visual>
    <!-- <collision>
      <origin xyz="0 0 0" rpy="0 0 0" />
      <geometry>
        <mesh filename="meshes/R_knee_pitch_black_link.STL" />
      </geometry>
    </collision> -->
  </link>
  <!-- <joint name="R_knee_pitch_black" type="fixed">
    <origin xyz="0 0 -0.357" rpy="0 0 0" />
    <parent link="R_hip_yaw_black_link" />
    <child link="R_knee_pitch_black_link" />
    <axis xyz="0 0 0" />
  </joint> -->
  <joint name="R_knee_pitch_black" type="fixed">
    <origin xyz="0 0 0" rpy="0 0 0" />
    <parent link="R_knee_pitch_link" />
    <child link="R_knee_pitch_black_link" />
    <axis xyz="0 0 0" />
  </joint>
  <link name="R_knee_pitch_link">
    <inertial>
      <origin xyz="0.00459772 0 -0.22342401" rpy="0 0 0" />
      <mass value="1.2" />
      <inertia ixx="0.01015001" ixy="0.00000002" ixz="0.00082886" iyy="0.01039687" iyz="0.00000003" izz="0.00150910" />
    </inertial>
    <visual>
      <origin xyz="0 0 0" rpy="0 0 0" />
      <geometry>
        <mesh filename="meshes/R_knee_pitch_link.STL" />
      </geometry>
      <material name="">
        <color rgba="1 1 1 1" />
      </material>
    </visual>
    <collision>
      <origin xyz="0 0 0" rpy="0 0 0" />
      <geometry>
        <mesh filename="meshes/R_knee_pitch_link.STL" />
      </geometry>
    </collision>
  </link>
  <!-- <joint name="R_knee_pitch" type="revolute">
    <origin xyz="0 0 0" rpy="0 0 0" />
    <parent link="R_knee_pitch_black_link" />
    <child link="R_knee_pitch_link" />
    <axis xyz="0 -1 0" />
    <limit lower="-2.3562" upper="0" effort="93.6" velocity="90" />
  </joint> -->
  <joint name="R_knee_pitch" type="revolute">
    <origin xyz="0 0 -0.357" rpy="0 0 0" />
    <parent link="R_hip_yaw_black_link" />
    <child link="R_knee_pitch_link" />
    <axis xyz="0 -1 0" />
    <limit lower="-2.3562" upper="0" effort="93.6" velocity="90" />
  </joint>
  <link name="R_ankle_pitch_Link">
    <inertial>
      <origin xyz="0 0 -0.03720405" rpy="0 0 0" />
      <mass value="0.2" />
      <inertia ixx="0.00020542" ixy="0.0000000" ixz="0.00000000" iyy="0.00022529" iyz="0.00000000" izz="0.00007465" />
    </inertial>
    <visual>
      <origin xyz="0 0 0" rpy="0 0 0" />
      <geometry>
        <mesh filename="meshes/R_ankle_pitch_Link.STL" />
      </geometry>
      <material name="">
        <color rgba="0.41961 0.41961 0.41961 1" />
      </material>
    </visual>
    <collision>
      <origin xyz="0 0 0" rpy="0 0 0" />
      <geometry>
        <mesh filename="meshes/R_ankle_pitch_Link.STL" />
      </geometry>
    </collision>
  </link>
  <joint name="R_ankle_pitch" type="revolute">
    <origin xyz="0 0 -0.43" rpy="0 0 0" />
    <parent link="R_knee_pitch_link" />
    <child link="R_ankle_pitch_Link" />
    <axis xyz="0 -1 0" />
    <limit lower="-1.309" upper="1.309" effort="64.8" velocity="130" />
  </joint>
  <link name="R_ankle_roll_link">
    <inertial>
      <origin xyz="0.04505385 0.00001354 -0.02342946" rpy="0 0 0" />
      <mass value="0.6" />
      <inertia ixx="0.00041777" ixy="0.00000006" ixz="-0.00009663" iyy="0.00376485" iyz="-0.00000000" izz="0.00406581" />
    </inertial>
    <visual>
      <origin xyz="0 0 0" rpy="0 0 0" />
      <geometry>
        <mesh filename="meshes/R_ankle_roll_link.STL" />
      </geometry>
      <material name="">
        <color rgba="0.41961 0.41961 0.41961 1" />
      </material>
    </visual>
    <!-- <collision>
      <origin xyz="0 0 0" rpy="0 0 0" />
      <geometry>
        <mesh filename="meshes/R_ankle_roll_link.STL" />
      </geometry>
    </collision> -->
<!--    <collision>-->
<!--      <origin xyz="-0.066 0.03 -0.034" rpy="0 0 0"/>-->
<!--      <geometry>-->
<!--        <sphere radius="0.005"/>-->
<!--      </geometry>-->
<!--    </collision>-->
<!--    <collision>-->
<!--      <origin xyz="-0.066 -0.03 -0.034" rpy="0 0 0"/>-->
<!--      <geometry>-->
<!--        <sphere radius="0.005"/>-->
<!--      </geometry>-->
<!--    </collision>-->
<!--    <collision>-->
<!--      <origin xyz="0.16 0.035 -0.034" rpy="0 0 0"/>-->
<!--      <geometry>-->
<!--        <sphere radius="0.005"/>-->
<!--      </geometry>-->
<!--    </collision>-->
<!--    <collision>-->
<!--      <origin xyz="0.16 -0.035 -0.034" rpy="0 0 0"/>-->
<!--      <geometry>-->
<!--        <sphere radius="0.005"/>-->
<!--      </geometry>-->
<!--    </collision>-->
<!--    <collision>-->
<!--      <origin xyz="0.042 0.0 -0.0335" rpy="0 0 0"/>-->
<!--      <geometry>-->
<!--        <box size="0.2 0.05 0.01"/>-->
<!--      </geometry>-->
<!--    </collision>-->
    <collision> <origin xyz="0.04 0.0 0.00" rpy="0 0 0"/> <geometry> <box size="0.20 0.06 0.1"/> </geometry> </collision>
    <collision> <origin xyz="-0.09 -0.0   -0.0340" rpy="0 0 0"/> <geometry> <sphere radius="0.005"/> </geometry> </collision>
    <collision> <origin xyz=" 0.18 -0.0   -0.0340" rpy="0 0 0"/> <geometry> <sphere radius="0.005"/> </geometry> </collision>
    <collision> <origin xyz=" 0.12 -0.046 -0.0340" rpy="0 0 0"/> <geometry> <sphere radius="0.005"/> </geometry> </collision>
    <collision> <origin xyz=" 0.12  0.046 -0.0340" rpy="0 0 0"/> <geometry> <sphere radius="0.005"/> </geometry> </collision>
    <collision> <origin xyz="-0.03  0.033 -0.0340" rpy="0 0 0"/> <geometry> <sphere radius="0.005"/> </geometry> </collision>
    <collision> <origin xyz="-0.03 -0.033 -0.0340" rpy="0 0 0"/> <geometry> <sphere radius="0.005"/> </geometry> </collision>
  </link>
  <joint name="R_ankle_roll" type="revolute">
    <origin xyz="0 0 -0.058" rpy="0 0 0" />
    <parent link="R_ankle_pitch_Link" />
    <child link="R_ankle_roll_link" />
    <axis xyz="-1 0 0" />
    <limit lower="-0.5236" upper="0.5236" effort="7.7" velocity="20" />
  </joint>
  <link name="R_ankle_roll_white_link">
    <inertial>
      <origin xyz="0.052694 1.2918E-07 0.0076217" rpy="0 0 0" />
      <mass value="0.05" />
      <inertia ixx="0.00038883" ixy="1.1816E-09" ixz="0.00022024" iyy="0.0030036" iyz="9.5402E-10" izz="0.0031991" />
    </inertial>
    <visual>
      <origin xyz="0 0 0" rpy="0 0 0" />
      <geometry>
        <mesh filename="meshes/R_ankle_roll_white_link.STL" />
      </geometry>
      <material name="">
        <color rgba="1 1 1 1" />
      </material>
    </visual>
    <!-- <collision>
      <origin xyz="0 0 0" rpy="0 0 0" />
      <geometry>
        <mesh filename="meshes/R_ankle_roll_white_link.STL" />
      </geometry>
    </collision> -->
  </link>
  <joint name="R_ankle_roll_white" type="fixed">
    <origin xyz="0 0 0" rpy="0 0 0" />
    <parent link="R_ankle_roll_link" />
    <child link="R_ankle_roll_white_link" />
    <axis xyz="0 0 0" />
  </joint>
  <link name="waist_yaw_link">
    <inertial>
      <origin xyz="0 0 0.00521207" rpy="0 0 0" />
      <mass value="0.3" />
      <inertia ixx="0.00106795" ixy="0.0000000" ixz="0.00000000" iyy="0.00113466" iyz="-0.00000004" izz="0.00146289" />
    </inertial>
    <visual>
      <origin xyz="0 0 0" rpy="0 0 0" />
      <geometry>
        <mesh filename="meshes/waist_yaw_link.STL" />
      </geometry>
      <material name="">
        <color rgba="0.41961 0.41961 0.41961 1" />
      </material>
    </visual>
    <!-- <collision>
      <origin xyz="0 0 0" rpy="0 0 0" />
      <geometry>
        <mesh filename="meshes/waist_yaw_link.STL" />
      </geometry>
    </collision> -->
  </link>
  <joint name="waist_yaw" type="revolute">
    <origin xyz="0 0 0.1716" rpy="0 0 0" />
    <parent link="pelvis_link" />
    <child link="waist_yaw_link" />
    <axis xyz="0 0 1" />
    <limit lower="-0.7854" upper="0.7854" effort="72" velocity="117.5" />
  </joint>
  <link name="waist_roll_link">
    <inertial>
      <origin xyz="0 0 0" rpy="0 0 0" />
      <mass value="2.1" />
      <inertia ixx="0.00168" ixy="0.00000000" ixz="0.00000000" iyy="0.001960000" iyz="0" izz="0.001960000" />
    </inertial>
    <visual>
      <origin xyz="0 0 0" rpy="0 0 0" />
      <geometry>
        <mesh filename="meshes/waist_roll_link.STL" />
      </geometry>
      <material name="">
        <color rgba="1 1 1 1" />
      </material>
    </visual>
    <!-- <collision>
      <origin xyz="0 0 0" rpy="0 0 0" />
      <geometry>
        <mesh filename="meshes/waist_roll_link.STL" />
      </geometry>
    </collision> -->
  </link>
  <joint name="waist_roll" type="revolute">
    <origin xyz="0 0 0" rpy="0 0 0" />
    <parent link="waist_yaw_link" />
    <child link="waist_roll_link" />
    <axis xyz="1 0 0" />
    <limit lower="-0.4363" upper="0.4363" effort="36" velocity="235" />
  </joint>
  <link name="torso_link">
    <inertial>
      <origin xyz="0.00176915 0 0.35267222" rpy="0 0 0" />
      <mass value="10" />
      <inertia ixx="0.08821683" ixy="0.00000007" ixz="-0.00086269" iyy="0.08305526" iyz="0.00000008" izz="0.08533186" />
    </inertial>
    <visual>
      <origin xyz="0 0 0" rpy="0 0 0" />
      <geometry>
        <mesh filename="meshes/torso_link.STL" />
      </geometry>
      <material name="">
        <color rgba="1 1 1 1" />
      </material>
    </visual>
    <collision>
      <origin xyz="0 0 0" rpy="0 0 0" />
      <geometry>
        <mesh filename="meshes/torso_link.STL" />
      </geometry>
    </collision>
  </link>
  <joint name="torso" type="fixed">
    <origin xyz="0 0 -0.1716" rpy="0 0 0" />
    <parent link="waist_roll_link" />
    <child link="torso_link" />
    <axis xyz="0 0 0" />
  </joint>
  <link name="head_pitch_link">
    <inertial>
      <origin xyz="-0.0019436 -4.9792E-08 0.010022" rpy="0 0 0" />
      <mass value="1.1" />
      <inertia ixx="0.00025617" ixy="-1.092E-09" ixz="1.1163E-06" iyy="0.00040167" iyz="-3.0801E-10" izz="0.00032194" />
    </inertial>
    <visual>
      <origin xyz="0 0 0" rpy="0 0 0" />
      <geometry>
        <mesh filename="meshes/head_pitch_link.STL" />
      </geometry>
      <material name="">
        <color rgba="0.41961 0.41961 0.41961 1" />
      </material>
    </visual>
    <!-- <collision>
      <origin xyz="0 0 0" rpy="0 0 0" />
      <geometry>
        <mesh filename="meshes/head_pitch_link.STL" />
      </geometry>
    </collision> -->
  </link>
  <joint name="head_pitch" type="fixed">
    <origin xyz="0 0 0.5176" rpy="0 0 0" />
    <parent link="torso_link" />
    <child link="head_pitch_link" />
    <axis xyz="0 -1 0" />
    <limit lower="-0.2618" upper="0.5236" effort="6.8" velocity="30" />
  </joint>
  <link name="head_yaw_link">
    <inertial>
      <origin xyz="0.0078393 -3.5328E-05 0.10144" rpy="0 0 0" />
      <mass value="2" />
      <inertia ixx="0.01342" ixy="3.8543E-06" ixz="-0.00032559" iyy="0.014149" iyz="5.9802E-06" izz="0.0094371" />
    </inertial>
    <visual>
      <origin xyz="0 0 0" rpy="0 0 0" />
      <geometry>
        <mesh filename="meshes/head_yaw_link.STL" />
      </geometry>
      <material name="">
        <color rgba="0.41961 0.41961 0.41961 1" />
      </material>
    </visual>
    <!-- <collision>
      <origin xyz="0 0 0" rpy="0 0 0" />
      <geometry>
        <mesh filename="meshes/head_yaw_link.STL" />
      </geometry>
    </collision> -->
  </link>
  <joint name="head_yaw" type="fixed">
    <origin xyz="0 0 0.06128" rpy="0 0 0" />
    <parent link="head_pitch_link" />
    <child link="head_yaw_link" />
    <axis xyz="0 0 1" />
    <limit lower="-1.047" upper="1.047" effort="6.8" velocity="30" />
  </joint>
  <link name="head_lamp_link">
    <inertial>
      <origin xyz="0.012591 -0.00014116 0.08922" rpy="0 0 0" />
      <mass value="0.01" />
      <inertia ixx="3.7811E-05" ixy="4.0394E-09" ixz="2.6482E-06" iyy="1.4668E-05" iyz="-3.798E-09" izz="3.587E-05" />
    </inertial>
    <visual>
      <origin xyz="0 0 0" rpy="0 0 0" />
      <geometry>
        <mesh filename="meshes/head_lamp_link.STL" />
      </geometry>
      <material name="">
        <color rgba="0 1 1 1" />
      </material>
    </visual>
    <!-- <collision>
      <origin xyz="0 0 0" rpy="0 0 0" />
      <geometry>
        <mesh filename="meshes/head_lamp_link.STL" />
      </geometry>
    </collision> -->
  </link>
  <joint name="head_lamp" type="fixed">
    <origin xyz="0 0 0" rpy="0 0 0" />
    <parent link="head_yaw_link" />
    <child link="head_lamp_link" />
    <axis xyz="0 0 0" />
  </joint>
  <link name="face_link">
    <inertial>
      <origin xyz="0.079201 -0.00011607 0.075742" rpy="0 0 0" />
      <mass value="0.01" />
      <inertia ixx="0.0012449" ixy="-7.0495E-09" ixz="-4.2681E-05" iyy="0.00089036" iyz="-1.5465E-08" izz="0.00052426" />
    </inertial>
    <visual>
      <origin xyz="0 0 0" rpy="0 0 0" />
      <geometry>
        <mesh filename="meshes/face_link.STL" />
      </geometry>
      <material name="">
        <color rgba="0.2 0.2 0.2 1" />
      </material>
    </visual>
    <!-- <collision>
      <origin xyz="0 0 0" rpy="0 0 0" />
      <geometry>
        <mesh filename="meshes/face_link.STL" />
      </geometry>
    </collision> -->
  </link>
  <joint name="face" type="fixed">
    <origin xyz="0 0 0" rpy="0 0 0" />
    <parent link="head_yaw_link" />
    <child link="face_link" />
    <axis xyz="0 0 0" />
  </joint>
  <link name="L_shoulder_pitch_link">
    <inertial>
      <origin xyz="-0.00083973 0.050353 0.0019496" rpy="0 0 0" />
      <mass value="1.7" />
      <inertia ixx="0.0014141" ixy="1.3493E-05" ixz="2.5809E-06" iyy="0.00095389" iyz="-7.8113E-06" izz="0.0012992" />
    </inertial>
    <visual>
      <origin xyz="0 0 0" rpy="0 0 0" />
      <geometry>
        <mesh filename="meshes/L_shoulder_pitch_link.STL" />
      </geometry>
      <material name="">
        <color rgba="0.41176 0.41176 0.41176 1" />
      </material>
    </visual>
    <!-- <collision>
      <origin xyz="0 0 0" rpy="0 0 0" />
      <geometry>
        <mesh filename="meshes/L_shoulder_pitch_link.STL" />
      </geometry>
    </collision> -->
  </link>
  <joint name="L_shoulder_pitch" type="revolute">
    <origin xyz="-0.006 0.1025 0.4456" rpy="0 0 0" />
    <parent link="torso_link" />
    <child link="L_shoulder_pitch_link" />
    <axis xyz="0 -1 0" />
    <limit lower="-1.5708" upper="3.1416" effort="38" velocity="30" />
  </joint>
  <link name="L_shoulder_roll_link">
    <inertial>
      <origin xyz="-0.0022667 0.00026948 -0.050968" rpy="0 0 0" />
      <mass value="1.2" />
      <inertia ixx="0.0025126" ixy="3.3211E-06" ixz="6.6092E-05" iyy="0.0031084" iyz="-2.0912E-05" izz="0.0018992" />
    </inertial>
    <visual>
      <origin xyz="0 0 0" rpy="0 0 0" />
      <geometry>
        <mesh filename="meshes/L_shoulder_roll_link.STL" />
      </geometry>
      <material name="">
        <color rgba="1 1 1 1" />
      </material>
    </visual>
    <!-- <collision>
      <origin xyz="0 0 0" rpy="0 0 0" />
      <geometry>
        <mesh filename="meshes/L_shoulder_roll_link.STL" />
      </geometry>
    </collision> -->
  </link>
  <joint name="L_shoulder_roll" type="revolute">
    <origin xyz="0 0.0845 0" rpy="0 0 0" />
    <parent link="L_shoulder_pitch_link" />
    <child link="L_shoulder_roll_link" />
    <axis xyz="1 0 0" />
    <limit lower="-0.1745" upper="1.5708" effort="38" velocity="30" />
  </joint>
  <link name="L_shoulder_yaw_link">
    <inertial>
      <origin xyz="-6.043E-07 0.00099258 -0.042402" rpy="0 0 0" />
      <mass value="1.1" />
      <inertia ixx="0.00085174" ixy="-5.8193E-10" ixz="2.8655E-09" iyy="0.0009509" iyz="1.5244E-05" izz="0.00056851" />
    </inertial>
    <visual>
      <origin xyz="0 0 0" rpy="0 0 0" />
      <geometry>
        <mesh filename="meshes/L_shoulder_yaw_link.STL" />
      </geometry>
      <material name="">
        <color rgba="0.41176 0.41176 0.41176 1" />
      </material>
    </visual>
    <!-- <collision>
      <origin xyz="0 0 0" rpy="0 0 0" />
      <geometry>
        <mesh filename="meshes/L_shoulder_yaw_link.STL" />
      </geometry>
    </collision> -->
  </link>
  <joint name="L_shoulder_yaw" type="revolute">
    <origin xyz="0.00015 0 -0.136" rpy="0 0 0" />
    <parent link="L_shoulder_roll_link" />
    <child link="L_shoulder_yaw_link" />
    <axis xyz="0 0 1" />
    <limit lower="-0.5" upper="1.0" effort="14" velocity="30" />
  </joint>
  <link name="L_elbow_pitch_link">
    <inertial>
      <origin xyz="-0.0022581 0.0054089 -0.022141" rpy="0 0 0" />
      <mass value="0.56" />
      <inertia ixx="0.0006138" ixy="-2.8032E-06" ixz="-2.9913E-06" iyy="0.00040913" iyz="-1.0184E-05" izz="0.00049105" />
    </inertial>
    <visual>
      <origin xyz="0 0 0" rpy="0 0 0" />
      <geometry>
        <mesh filename="meshes/L_elbow_pitch_link.STL" />
      </geometry>
      <material name="">
        <color rgba="0.41176 0.41176 0.41176 1" />
      </material>
    </visual>
    <!-- <collision>
      <origin xyz="0 0 0" rpy="0 0 0" />
      <geometry>
        <mesh filename="meshes/L_elbow_pitch_link.STL" />
      </geometry>
    </collision> -->
  </link>
  <joint name="L_elbow_pitch" type="revolute">
    <origin xyz="0 0 -0.079866" rpy="0 -1.507 0" />
    <parent link="L_shoulder_yaw_link" />
    <child link="L_elbow_pitch_link" />
    <axis xyz="0 -1 0" />
    <limit lower="-1.4" upper="1.0" effort="6.8" velocity="30" />
  </joint>
  <link name="L_elbow_pitch_white_link">
    <inertial>
      <origin xyz="-0.0012412 0.0040006 -0.08694" rpy="0 0 0" />
      <mass value="0.05" />
      <inertia ixx="0.00034341" ixy="-7.6296E-10" ixz="1.6271E-05" iyy="0.00035224" iyz="3.5802E-10" izz="0.00047214" />
    </inertial>
    <visual>
      <origin xyz="0 0 0" rpy="0 0 0" />
      <geometry>
        <mesh filename="meshes/L_elbow_pitch_white_link.STL" />
      </geometry>
      <material name="">
        <color rgba="1 1 1 1" />
      </material>
    </visual>
    <!-- <collision>
      <origin xyz="0 0 0" rpy="0 0 0" />
      <geometry>
        <mesh filename="meshes/L_elbow_pitch_white_link.STL" />
      </geometry>
    </collision> -->
  </link>
  <joint name="L_elbow_pitch_white" type="fixed">
    <origin xyz="0 0 0" rpy="0 0 0" />
    <parent link="L_elbow_pitch_link" />
    <child link="L_elbow_pitch_white_link" />
    <axis xyz="0 0 0" />
  </joint>
  <link name="L_wirst_yaw_link">
    <inertial>
      <origin xyz="-1.1103E-05 6.7439E-07 -0.052024" rpy="0 0 0" />
      <mass value="0.6" />
      <inertia ixx="0.0011875" ixy="1.3935E-08" ixz="-4.7323E-07" iyy="0.0012876" iyz="1.5061E-08" izz="0.00068033" />
    </inertial>
    <visual>
      <origin xyz="0 0 0" rpy="0 0 0" />
      <geometry>
        <mesh filename="meshes/L_wirst_yaw_link.STL" />
      </geometry>
      <material name="">
        <color rgba="1 1 1 1" />
      </material>
    </visual>
    <!-- <collision>
      <origin xyz="0 0 0" rpy="0 0 0" />
      <geometry>
        <mesh filename="meshes/L_wirst_yaw_link.STL" />
      </geometry>
    </collision> -->
  </link>
  <joint name="L_wirst_yaw" type="revolute">
    <origin xyz="0 0.004 -0.11773" rpy="0 0 0" />
    <parent link="L_elbow_pitch_white_link" />
    <child link="L_wirst_yaw_link" />
    <axis xyz="0 0 1" />
    <limit lower="-2.4871" upper="2.4871" effort="6.8" velocity="30" />
  </joint>
  <link name="L_wrist_roll_link">
    <inertial>
      <origin xyz="8.5114E-05 1.9079E-09 -0.027615" rpy="0 0 0" />
      <mass value="0.32" />
      <inertia ixx="4.401E-05" ixy="-1.7325E-12" ixz="-2.0821E-07" iyy="4.4341E-05" iyz="-2.0652E-12" izz="3.8299E-05" />
    </inertial>
    <visual>
      <origin xyz="0 0 0" rpy="0 0 0" />
      <geometry>
        <mesh filename="meshes/L_wrist_roll_link.STL" />
      </geometry>
      <material name="">
        <color rgba="0.62745 0.62745 0.62745 1" />
      </material>
    </visual>
    <!-- <collision>
      <origin xyz="0 0 0" rpy="0 0 0" />
      <geometry>
        <mesh filename="meshes/L_wrist_roll_link.STL" />
      </geometry>
    </collision> -->
  </link>
  <joint name="L_wrist_roll" type="fixed">
    <origin xyz="0 0 -0.1159" rpy="0 0 0" />
    <parent link="L_wirst_yaw_link" />
    <child link="L_wrist_roll_link" />
    <axis xyz="1 0 0" />
    <limit lower="-0.5236" upper="0.5236" effort="6.8" velocity="30" />
  </joint>
  <link name="L_wrist_pitch_link">
    <inertial>
      <origin xyz="0.0041742 -0.0016296 -0.089473" rpy="0 0 0" />
      <mass value="0.2" />
      <inertia ixx="0.000617" ixy="4.7665E-05" ixz="1.6112E-05" iyy="0.00068349" iyz="-2.8688E-05" izz="0.00031261" />
    </inertial>
    <visual>
      <origin xyz="0 0 0" rpy="0 0 0" />
      <geometry>
        <mesh filename="meshes/L_wrist_pitch_link.STL" />
      </geometry>
      <material name="">
        <color rgba="1 1 1 1" />
      </material>
    </visual>
    <!-- <collision>
      <origin xyz="0 0 0" rpy="0 0 0" />
      <geometry>
        <mesh filename="meshes/L_wrist_pitch_link.STL" />
      </geometry>
    </collision> -->
  </link>
  <joint name="L_wrist_pitch" type="fixed">
    <origin xyz="0 0 -0.03" rpy="0 0 0" />
    <parent link="L_wrist_roll_link" />
    <child link="L_wrist_pitch_link" />
    <axis xyz="0 -1 0" />
    <limit lower="-1.309" upper="1.309" effort="1.6" velocity="30" />
  </joint>
  <link name="R_shoulder_pitch_link">
    <inertial>
      <origin xyz="-0.00083973 -0.050353 0.0019495" rpy="0 0 0" />
      <mass value="1.7" />
      <inertia ixx="0.0014141" ixy="-1.3493E-05" ixz="2.5811E-06" iyy="0.00095389" iyz="7.8123E-06" izz="0.0012992" />
    </inertial>
    <visual>
      <origin xyz="0 0 0" rpy="0 0 0" />
      <geometry>
        <mesh filename="meshes/R_shoulder_pitch_link.STL" />
      </geometry>
      <material name="">
        <color rgba="0.41961 0.41961 0.41961 1" />
      </material>
    </visual>
    <!-- <collision>
      <origin xyz="0 0 0" rpy="0 0 0" />
      <geometry>
        <mesh filename="meshes/R_shoulder_pitch_link.STL" />
      </geometry>
    </collision> -->
  </link>
  <joint name="R_shoulder_pitch" type="revolute">
    <origin xyz="-0.006 -0.1025 0.4456" rpy="0 0 0" />
    <parent link="torso_link" />
    <child link="R_shoulder_pitch_link" />
    <axis xyz="0 -1 0" />
    <limit lower="-1.5708" upper="3.1416" effort="38" velocity="30" />
  </joint>
  <link name="R_shoulder_roll_link">
    <inertial>
      <origin xyz="-0.0022681 -0.00026962 -0.050965" rpy="0 0 0" />
      <mass value="1.2" />
      <inertia ixx="0.0025124" ixy="-3.4472E-06" ixz="6.5967E-05" iyy="0.0031084" iyz="2.084E-05" izz="0.0018993" />
    </inertial>
    <visual>
      <origin xyz="0 0 0" rpy="0 0 0" />
      <geometry>
        <mesh filename="meshes/R_shoulder_roll_link.STL" />
      </geometry>
      <material name="">
        <color rgba="1 1 1 1" />
      </material>
    </visual>
    <!-- <collision>
      <origin xyz="0 0 0" rpy="0 0 0" />
      <geometry>
        <mesh filename="meshes/R_shoulder_roll_link.STL" />
      </geometry>
    </collision> -->
  </link>
  <joint name="R_shoulder_roll" type="revolute">
    <origin xyz="0 -0.0845 0" rpy="0 0 0" />
    <parent link="R_shoulder_pitch_link" />
    <child link="R_shoulder_roll_link" />
    <axis xyz="-1 0 0" />
    <limit lower="-0.1745" upper="1.5708" effort="38" velocity="30" />
  </joint>
  <link name="R_shoulder_yaw_link">
    <inertial>
      <origin xyz="-6.4993E-08 -0.00099228 -0.042402" rpy="0 0 0" />
      <mass value="1.1" />
      <inertia ixx="0.00085174" ixy="-9.7696E-09" ixz="2.5048E-09" iyy="0.00095087" iyz="-1.5247E-05" izz="0.00056849" />
    </inertial>
    <visual>
      <origin xyz="0 0 0" rpy="0 0 0" />
      <geometry>
        <mesh filename="meshes/R_shoulder_yaw_link.STL" />
      </geometry>
      <material name="">
        <color rgba="0.41176 0.41176 0.41176 1" />
      </material>
    </visual>
    <!-- <collision>
      <origin xyz="0 0 0" rpy="0 0 0" />
      <geometry>
        <mesh filename="meshes/R_shoulder_yaw_link.STL" />
      </geometry>
    </collision> -->
  </link>
  <joint name="R_shoulder_yaw" type="revolute">
    <origin xyz="0.00015 0 -0.136" rpy="0 0 0" />
    <parent link="R_shoulder_roll_link" />
    <child link="R_shoulder_yaw_link" />
    <axis xyz="0 0 -1" />
    <limit lower="-0.5" upper="1.0" effort="14" velocity="30" />
  </joint>
  <link name="R_elbow_pitch_link">
    <inertial>
      <origin xyz="-0.002259 -0.0054108 -0.022141" rpy="0 0 0" />
      <mass value="0.56" />
      <inertia ixx="0.0006138" ixy="2.8109E-06" ixz="-2.9816E-06" iyy="0.00040913" iyz="1.0184E-05" izz="0.00049105" />
    </inertial>
    <visual>
      <origin xyz="0 0 0" rpy="0 0 0" />
      <geometry>
        <mesh filename="meshes/R_elbow_pitch_link.STL" />
      </geometry>
      <material name="">
        <color rgba="0.41176 0.41176 0.41176 1" />
      </material>
    </visual>
    <!-- <collision>
      <origin xyz="0 0 0" rpy="0 0 0" />
      <geometry>
        <mesh filename="meshes/R_elbow_pitch_link.STL" />
      </geometry>
    </collision> -->
  </link>
  <joint name="R_elbow_pitch" type="revolute">
    <origin xyz="0 0 -0.079866" rpy="0 -1.507 0" />
    <parent link="R_shoulder_yaw_link" />
    <child link="R_elbow_pitch_link" />
    <axis xyz="0 -1 0" />
    <limit lower="-1.4" upper="1.0" effort="6.8" velocity="30" />
  </joint>
  <link name="R_elbow_pitch_white_link">
    <inertial>
      <origin xyz="-0.0012428 -0.0039994 -0.08694" rpy="0 0 0" />
      <mass value="0.05" />
      <inertia ixx="0.00034342" ixy="1.9111E-08" ixz="1.6262E-05" iyy="0.00035221" iyz="1.7788E-10" izz="0.00047212" />
    </inertial>
    <visual>
      <origin xyz="0 0 0" rpy="0 0 0" />
      <geometry>
        <mesh filename="meshes/R_elbow_pitch_white_link.STL" />
      </geometry>
      <material name="">
        <color rgba="1 1 1 1" />
      </material>
    </visual>
    <!-- <collision>
      <origin xyz="0 0 0" rpy="0 0 0" />
      <geometry>
        <mesh filename="meshes/R_elbow_pitch_white_link.STL" />
      </geometry>
    </collision> -->
  </link>
  <joint name="R_elbow_pitch_white" type="fixed">
    <origin xyz="0 0 0" rpy="0 0 0" />
    <parent link="R_elbow_pitch_link" />
    <child link="R_elbow_pitch_white_link" />
    <axis xyz="0 0 0" />
  </joint>
  <link name="R_wrist_yaw_link">
    <inertial>
      <origin xyz="-9.2933E-06 -8.8833E-07 -0.052023" rpy="0 0 0" />
      <mass value="0.6" />
      <inertia ixx="0.0011875" ixy="4.2412E-08" ixz="-4.8954E-07" iyy="0.0012876" iyz="-3.6551E-10" izz="0.00068036" />
    </inertial>
    <visual>
      <origin xyz="0 0 0" rpy="0 0 0" />
      <geometry>
        <mesh filename="meshes/R_wrist_yaw_link.STL" />
      </geometry>
      <material name="">
        <color rgba="1 1 1 1" />
      </material>
    </visual>
    <!-- <collision>
      <origin xyz="0 0 0" rpy="0 0 0" />
      <geometry>
        <mesh filename="meshes/R_wrist_yaw_link.STL" />
      </geometry>
    </collision> -->
  </link>
  <joint name="R_wrist_yaw" type="revolute">
    <origin xyz="0 -0.004 -0.11773" rpy="0 0 0" />
    <parent link="R_elbow_pitch_white_link" />
    <child link="R_wrist_yaw_link" />
    <axis xyz="0 0 -1" />
    <limit lower="-2.4871" upper="2.4871" effort="6.8" velocity="30" />
  </joint>
  <link name="R_wrist_roll_link">
    <inertial>
      <origin xyz="8.5115E-05 -1.9245E-09 -0.027615" rpy="0 0 0" />
      <mass value="0.32" />
      <inertia ixx="4.401E-05" ixy="-5.391E-13" ixz="-2.0821E-07" iyy="4.4341E-05" iyz="1.9185E-12" izz="3.8299E-05" />
    </inertial>
    <visual>
      <origin xyz="0 0 0" rpy="0 0 0" />
      <geometry>
        <mesh filename="meshes/R_wrist_roll_link.STL" />
      </geometry>
      <material name="">
        <color rgba="0.41961 0.41961 0.41961 1" />
      </material>
    </visual>
    <!-- <collision>
      <origin xyz="0 0 0" rpy="0 0 0" />
      <geometry>
        <mesh filename="meshes/R_wrist_roll_link.STL" />
      </geometry>
    </collision> -->
  </link>
  <joint name="R_wrist_roll" type="fixed">
    <origin xyz="0 0 -0.1159" rpy="0 0 0" />
    <parent link="R_wrist_yaw_link" />
    <child link="R_wrist_roll_link" />
    <axis xyz="-1 0 0" />
    <limit lower="-0.5236" upper="0.5236" effort="6.8" velocity="30" />
  </joint>
  <link name="R_wrist_pitch_link">
    <inertial>
      <origin xyz="0.0041724 0.001631 -0.08947" rpy="0 0 0" />
      <mass value="0.2" />
      <inertia ixx="0.000617" ixy="-4.7673E-05" ixz="1.6111E-05" iyy="0.0006835" iyz="2.8687E-05" izz="0.00031263" />
    </inertial>
    <visual>
      <origin xyz="0 0 0" rpy="0 0 0" />
      <geometry>
        <mesh filename="meshes/R_wrist_pitch_link.STL" />
      </geometry>
      <material name="">
        <color rgba="1 1 1 1" />
      </material>
    </visual>
    <!-- <collision>
      <origin xyz="0 0 0" rpy="0 0 0" />
      <geometry>
        <mesh filename="meshes/R_wrist_pitch_link.STL" />
      </geometry>
    </collision> -->
  </link>
  <joint name="R_wrist_pitch" type="fixed">
    <origin xyz="0 0 -0.03" rpy="0 0 0" />
    <parent link="R_wrist_roll_link" />
    <child link="R_wrist_pitch_link" />
    <axis xyz="0 -1 0" />
    <limit lower="-1.309" upper="1.309" effort="1.6" velocity="30" />
  </joint>
  <link name="logo_link">
    <inertial>
      <origin xyz="0.10072 -0.0012647 0.42985" rpy="0 0 0" />
      <mass value="0.05" />
      <inertia ixx="5.4947E-08" ixy="2.1102E-09" ixz="1.3394E-08" iyy="2.8719E-08" iyz="-3.0137E-09" izz="4.5197E-08" />
    </inertial>
    <visual>
      <origin xyz="0 0 0" rpy="0 0 0" />
      <geometry>
        <mesh filename="meshes/logo_link.STL" />
      </geometry>
      <material name="">
        <color rgba="0.2 0.2 0.2 1" />
      </material>
    </visual>
    <!-- <collision>
      <origin xyz="0 0 0" rpy="0 0 0" />
      <geometry>
        <mesh filename="meshes/logo_link.STL" />
      </geometry>
    </collision> -->
  </link>
  <joint name="logo" type="fixed">
    <origin xyz="0 0 0" rpy="0 0 0" />
    <parent link="torso_link" />
    <child link="logo_link" />
    <axis xyz="0 0 0" />
  </joint>
  <link name="torso_black_link">
    <inertial>
      <origin xyz="-0.002039 4.4099E-06 0.40376" rpy="0 0 0" />
      <mass value="0.05" />
      <inertia ixx="0.0082211" ixy="3.7272E-07" ixz="1.4386E-06" iyy="0.0034327" iyz="-2.5582E-07" izz="0.010489" />
    </inertial>
    <visual>
      <origin xyz="0 0 0" rpy="0 0 0" />
      <geometry>
        <mesh filename="meshes/torso_black_link.STL" />
      </geometry>
      <material name="">
        <color rgba="0.41961 0.41961 0.41961 1" />
      </material>
    </visual>
    <!-- <collision>
      <origin xyz="0 0 0" rpy="0 0 0" />
      <geometry>
        <mesh filename="meshes/torso_black_link.STL" />
      </geometry>
    </collision> -->
  </link>
  <joint name="torso_black" type="fixed">
    <origin xyz="0 0 -0.1716" rpy="0 0 0" />
    <parent link="waist_roll_link" />
    <child link="torso_black_link" />
    <axis xyz="0 0 0" />
  </joint>
</robot>
